Workbook
Name townsRFI_1: 'Admin Unit'!$B$1:$B$7

Sheet Admin Unit
A1: School Admin Unit | B1: Location | C1: Date Record Updated | D1: Assistance Requested | E1: Report Tool PIN | F1: PWS? | G1: MWRA? | H1: Phase 1? | I1: # Schools | J1: Date for IM | K1: IM time | L1: Primary TAP | M1: Sample Plan | N1: Date First Sampled | O1: Laboratory | P1: Total # Samples | Q1: Status? | R1: DEP Region | S1: TAP(s) at IM | T1: Comments
A2: Dracut | B2: DRACUT | C2: 43102 | D2: Follow up | E2: 1a3c-c76b-6dc8 | F2: N | G2: N | H2: Y | I2: 1 | J2: none needed | L2: RL | Q2: Advice given | R2: Northeast | T2: Helped with Tool
A3: ReadingPS | B3: READING | C3: 43073 | D3: Follow up | E3: 56d8-2e54-5df8 | F3: N | G3: Y | H3: N | I3: 1 | J3: none needed | L3: RL | P3: =SUMIF(Facilities!A:A,"ReadingPS",Facilities!R:R) -> 0 | Q3: Advice given | R3: Northeast
A4: Springfield | B4: SPRINGFIELD | C4: 43102 | D4: Follow up | E4: 20d2-d383-fc0f | F4: N | G4: N | H4: Y | I4: 52 | J4: none needed | L4: RL | Q4: Advice given | R4: Western | T4: Helped with Cu Exceedances
A5: Wilmington | B5: WILMINGTON | C5: 43102 | D5: Follow up | E5: f51d-0aac-243b | F5: N | G5: Y | H5: Y | I5: 8 | J5: none needed | L5: RL | Q5: Advice given | R5: Northeast | T5: Helped with Tool
A6: WorcesterPS | B6: WORCESTER | C6: 43088 | D6: Follow up | E6: be6e-d2bf-4f12 | F6: N | G6: N | H6: Y | I6: 3 | J6: none needed | L6: RL | Q6: Advice given | R6: Central | T6: Helped with Tool and Lab Uploading of data
A7: AgawamPS | B7: AGAWAM | C7: 43259 | D7: Full sampling | E7: 4c48-1654-3b10 | F7: N | G7: N | H7: N | I7: 8 | J7: 43168 | K7: 9:30AM | L7: BH | M7: 8:8 | P7: =SUMIF(Facilities!A:A,"AgawamPS",Facilities!R:R) -> 535 | Q7: All Results sent | R7: Western
A8: UMassAmherstCEEC | B8: AMHERST | C8: 43153 | D8: Full sampling | E8: c101-79a5-b3fb | F8: N | G8: N | H8: N | I8: 1 | J8: 43027 | K8: 11:00AM | L8: RL | M8: 1:1 | N8: 43153 | O8: Alpha Analytical | P8: =SUMIF(Facilities!A:A,"UMassAmherstCEEC",Facilities!R:R) -> 7 | Q8: All results sent | R8: Western | S8: RL | T8: Sampled by John Tobiason
A9: NRSD | B9: BOLTON | C9: 43382 | D9: Full sampling | E9: d10e-83ca-eb31 | F9: Y | G9: N | H9: N | I9: 6 | J9: 43080 | K9: 10:00AM | L9: GB | M9: 6:6 | N9: 43146 | O9: RI Analytical | P9: =SUMIF(Facilities!A:A,"NRSD",Facilities!R:R) -> 566 | Q9: All results sent | R9: Central | S9: GB
A10: MasconometRSD | B10: BOXFORD | C10: 43269 | D10: Full sampling | E10: 2713-1fd5-c636 | F10: Y | G10: N | H10: N | I10: 1 | J10: 43244 | K10: 1:30PM | L10: BH | M10: 1:1 | N10: 43267 | O10: RI Analytical | P10: =SUMIF(Facilities!A:A,"MasconometRSD",Facilities!R:R) -> 91 | Q10: All results sent | R10: Northeast
A11: Tri-Town School Union | B11: BOXFORD | C11: 43273 | D11: Full sampling | E11: 2c25-1998-195a | F11: Y/N | G11: N | H11: N | I11: 6 | J11: 43244 | K11: 1:30PM | L11: BH | M11: 6:6 | N11: 43270 | O11: RI Analytical | P11: =SUMIF(Facilities!A:A,"Tri-Town School Union",Facilities!R:R) -> 612 | Q11: All Results sent | R11: Northeast
A12: BraintreePS | B12: BRAINTREE | C12: 43272 | D12: Full sampling | E12: f364-9b10-1331 | F12: N | G12: N | H12: N | I12: 10 | J12: 43223 | K12: 2:30PM | L12: GB | M12: 10:10 | N12: 43263 | O12: RI Analytical | P12: =SUMIF(Facilities!A:A,"BraintreePS",Facilities!R:R) -> 593 | Q12: All Results sent | R12: Southeast
A13: BRRSD | B13: BRIDGEWATER | C13: 43336 | D13: Full sampling | E13: 69b1-0b42-0241 | F13: N | G13: N | H13: N | I13: 7 | J13: 43208 | K13: 10:00AM | L13: TB | M13: 6:7 | N13: 43270 | O13: RI Analytical | P13: =SUMIF(Facilities!A:A,"BRRSD",Facilities!R:R) -> 499 | Q13: All Results sent | R13: Southeast
A14: SelfHelp | B14: BROCKTON | C14: 43325 | D14: Full sampling | E14: f4d5-ee2f-a606 | F14: N | G14: N | H14: N | I14: 3 | J14: 43244 | L14: GB | M14: 3:3 | N14: 43256 | O14: RI Analytical | P14: =SUMIF(Facilities!A:A,"SelfHelp",Facilities!R:R) -> 117 | Q14: All Results sent | R14: Southeast
A15: TritonRSD | B15: BYFIELD | C15: 43210 | D15: Full sampling | E15: 51d3-99e5-3ff9 | F15: N | G15: N | H15: N | I15: 4 | J15: 43054 | K15: 09:00AM | L15: GB | M15: 5:5 | N15: 43127 | O15: Granite | P15: =SUMIF(Facilities!A:A,"TritonRSD",Facilities!R:R) -> 642 | Q15: All Results sent | R15: Northeast | S15: GB,TB
A16: ClintonPS | B16: CLINTON | C16: 43243 | D16: Full sampling | E16: 454c-ae3b-9b86 | F16: N | G16: N | H16: N | I16: 4 | J16: 43147 | K16: 9:00AM | L16: LL | M16: 3 :4 | N16: 43204 | O16: MWRA | P16: =SUMIF(Facilities!A:A,"ClintonPS",Facilities!R:R) -> 314 | Q16: All Results sent | R16: Central | S16: LL
A17: Children's Workshop | B17: CUMBERLAND RI | C17: 43280 | D17: Full sampling | E17: 8db9-c1c8-fd68 | F17: N | G17: N | H17: N | I17: 8 | J17: 43242 | K17: 10:00AM | L17: GB | M17: 0:8 | N17: 43277 | O17: Barnstable | P17: =SUMIF(Facilities!A:A,"Children's Workshop",Facilities!R:R) -> 237 | Q17: All Results sent | R17: NE, C, SE
A18: Little Folks | B18: EAST BOSTON | C18: 43258 | D18: Full sampling | E18: a2ab-4c07-7ef5 | F18: N | G18: Y | H18: N | I18: 2 | J18: 43217 | K18: 10:00AM | L18: BH | M18: 2:2 | N18: 43257 | O18: MWRA | P18: =SUMIF(Facilities!A:A,"Little Folks",Facilities!R:R) -> 30 | Q18: All Results sent | R18: Northeast
A19: TEC-COOP | B19: EAST WALPOLE | C19: 43217 | D19: Full sampling | E19: 998e-32db-f396 | F19: N | G19: N | H19: N | I19: 1 | J19: 43199 | K19: 11:00AM | L19: GB | M19: 1:1 | N19: 43217 | O19: RI Analytical | P19: =SUMIF(Facilities!A:A,"TEC-COOP",Facilities!N:N) -> 41 | Q19: All Results sent | R19: Southeast | S19: GB
A20: TantasquaRSD | B20: FISKDALE | C20: 43328 | D20: Full sampling | E20: 0646-20fd-b0b2 | F20: Y | G20: N | H20: N | I20: 2 | J20: 43245 | K20: 9:00AM | L20: GB | M20: 2:2 | N20: 43258 | O20: RI Analytical | P20: =SUMIF(Facilities!A:A,"TantasquaRSD",Facilities!R:R) -> 134 | Q20: All Results sent | R20: Central | S20: TB
A21: GraftonPS | B21: GRAFTON | C21: 43187 | D21: Full sampling | E21: 564b-9d1d-ba83 | F21: N | G21: N | H21: N | I21: 6 | J21: 43076 | K21: 10:00AM | L21: LL | M21: 6:6 | N21: 43158 | O21: RI Analytical | P21: =SUMIF(Facilities!A:A,"GraftonPS",Facilities!R:R) -> 387 | Q21: All Results sent | R21: Central | S21: LL
A22: HaverhillComAct | B22: HAVERHILL | C22: 43265 | D22: Full sampling | E22: ccfc-01a5-1f2c | F22: N | G22: N | H22: N | I22: 3 | J22: 43229 | K22: 10:00AM | L22: GB | M22: 3:3 | N22: 43242 | O22: Granite | P22: =SUMIF(Facilities!A:A,"HaverhillComAct",Facilities!R:R) -> 59 | Q22: All Results sent | R22: Northeast | S22: GB
A23: PositiveRegard | B23: HOLYOKE | C23: 43277 | D23: Full sampling | E23: abca-e8e8-abf7 | F23: N | G23: N | H23: N | I23: 2 | J23: 43230 | K23: 9:30AM | L23: MI | M23: 2:2 | N23: 43239 | O23: Eurofins | P23: =SUMIF(Facilities!A:A,"PositiveRegard",Facilities!R:R) -> 31 | Q23: All Results sent | R23: Western | S23: MI
A24: WachusettRSD | B24: JEFFERSON | C24: 43143 | D24: Full sampling | E24: cfbc-de6f-1220 | F24: N | G24: N | H24: N | I24: 12 | J24: 43087 | K24: 9:00AM | L24: GB | M24: 12:12 | N24: 43125 | O24: Alpha Analytical | P24: =SUMIF(Facilities!A:A,"WachusettRSD",Facilities!R:R) -> 1215 | Q24: All results sent | R24: Central | S24: GB
A25: LeominsterPS | B25: LEOMINSTER | C25: 43129 | D25: Full sampling | E25: 185f-1c77-28c1 | F25: N | G25: N | H25: N | I25: 11 | J25: 43045 | K25: 10:00AM | L25: GB | M25: 9:11 | N25: 43109 | O25: Alpha Analytical | P25: =SUMIF(Facilities!A:A,"LeominsterPS",Facilities!R:R) -> 216 | Q25: All results sent | R25: Central | S25: GB
A26: LudlowPS | B26: LUDLOW | C26: 43277 | D26: Full sampling | E26: 2fa8-1f42-4e34 | F26: N | G26: N | H26: N | I26: 6 | J26: 43153 | K26: 09:30AM | L26: MI | M26: 6:6 | N26: 43218 | O26: Eurofins | P26: =SUMIF(Facilities!A:A,"LudlowPS",Facilities!R:R) -> 463 | Q26: All Results sent | R26: Western | S26: MI
A27: LunenburgPS | B27: LUNENBURG | C27: 43255 | D27: Full sampling | E27: d17f-4f5d-9910 | F27: N | G27: N | H27: N | I27: 4 | J27: 43231 | K27: 9:00AM | L27: GB | M27: 4:4 | N27: 43253 | O27: Granite | P27: =SUMIF(Facilities!A:A,"LunenburgPS",Facilities!R:R) -> 311 | Q27: All Results sent | R27: Central
A28: LynnfieldPS | B28: LYNNFIELD | C28: 43328 | D28: Full sampling | E28: c8a4-b8ab-6882 | F28: N | G28: Y | H28: N | I28: 4 | J28: 43223 | K28: 10:00AM | L28: GB | M28: 4:4 | N28: 43246 | O28: Granite | P28: =SUMIF(Facilities!A:A,"LynnfieldPS",Facilities!R:R) -> 420 | Q28: All Results sent | R28: Northeast | S28: GB
A29: MansfieldPS | B29: MANSFIELD | C29: 43143 | D29: Full sampling | E29: 74c0-e2f6-5dce | F29: N | G29: N | H29: N | I29: 5 | J29: 43055 | K29: 10:00AM | L29: GB | M29: 5:5 | N29: 43139 | O29: Alpha Analytical | P29: =SUMIF(Facilities!A:A,"MansfieldPS",Facilities!R:R) -> 504 | Q29: All results sent | R29: Southeast | S29: GB, TB
A30: MaynardPS | B30: MAYNARD | C30: 43236 | D30: Full sampling | E30: 48cf-a446-d8ca | F30: N | G30: N | H30: N | I30: 3 | J30: 43241 | K30: 9:30AM | L30: LL | M30: 0:3 | O30: RI Analytical | Q30: All Results sent | R30: Central | T30: Not responding to TAP
A31: NSWSD | B31: NEW SALEM | C31: 43210 | D31: Full sampling | E31: a822-7e6a-8e04 | F31: Y | G31: N | H31: N | I31: 1 | J31: 43130 | K31: 10:00AM | L31: MI | M31: 1:1 | N31: 43161 | O31: Granite | P31: =SUMIF(Facilities!A:A,"NSWSD",Facilities!R:R) -> 56 | Q31: All Results sent | R31: Western | S31: MI
A32: North ReadingPS | B32: NORTH READING | C32: 43280 | D32: Full sampling | E32: 89ba-0b5c-7901 | F32: N | G32: N | H32: N | I32: 5 | J32: 43222 | K32: 10:00AM | L32: GB | M32: 5:5 | N32: 43250 | O32: Alpha Analytical | P32: =SUMIF(Facilities!A:A,"North ReadingPS",Facilities!R:R) -> 385 | Q32: All Results sent | R32: Northeast
A33: SouthShoreCPS | B33: NORWELL | C33: 43255 | D33: Full sampling | E33: ceda-3e64-3a3c | F33: N | G33: N | H33: N | I33: 1 | J33: 43143 | K33: 01:00PM | L33: TB | M33: 1:1 | N33: 43231 | O33: Alpha Analytical | P33: =SUMIF(Facilities!A:A,"SouthShoreCPS",Facilities!R:R) -> 26 | Q33: All Results sent | R33: Southeast
A34: PittsfieldPS | B34: PITTSFIELD | C34: 43280 | D34: Full sampling | E34: f8f5-52a9-bad2 | F34: N | G34: N | H34: N | I34: 12 | J34: 43223 | K34: 10:00AM | L34: MI | M34: 11:12 | N34: 43246 | O34: Eurofins | P34: =SUMIF(Facilities!A:A,"PittsfieldPS",Facilities!R:R) -> 658 | Q34: All Results sent | R34: Western | S34: MI
A35: SBRSD | B35: SHEFFIELD | C35: 43313 | D35: Full sampling | E35: c3ee-b69c-0b74 | F35: N | G35: N | H35: N | I35: 2 | J35: 43223 | K35: 10:00AM | L35: MI | M35: 2:2 | N35: 43266 | O35: Eurofins | P35: =SUMIF(Facilities!A:A,"SBRSD",Facilities!R:R) -> 168 | Q35: All Results sent | R35: Western
A36: Shutesbury ES | B36: SHUTESBURY | C36: 43271 | D36: Full sampling | E36: 9b2e-c929-f1ad | F36: Y | G36: N | H36: N | I36: 1 | J36: 43249 | K36: 9:00AM | L36: JT | M36: 1:1 | N36: 43271 | O36: Eurofins | P36: =SUMIF(Facilities!A:A,"Shutesbury ES",Facilities!R:R) -> 40 | Q36: All Results sent | R36: Western
A37: South Hadley PS | B37: SOUTH HADLEY | C37: 43269 | D37: Full sampling | E37: 5486-e4cc-0d8f | F37: Y | G37: Y | H37: N | I37: 4 | J37: 43251 | K37: 9:30AM | L37: JT, RL | M37: 4:4 | N37: 43267 | O37: MWRA | P37: =SUMIF(Facilities!A:A,"South Hadley PS",Facilities!R:R) -> 263 | Q37: All Results sent | R37: Western | S37: JT, RL
A38: SEBRSD | B38: SPENCER | C38: 43273 | D38: Full sampling | E38: 1091-54f5-f19b | F38: N | G38: N | H38: N | I38: 4 | J38: 43213 | K38: 9:00AM | L38: LL | M38: 4:4 | N38: 43235 | O38: Alpha Analytical | P38: =SUMIF(Facilities!A:A,"SEBRSD",Facilities!R:R) -> 257 | Q38: All Results sent | R38: Central | S38: LL
A39: BaystateACPS | B39: SPRINGFIELD | C39: 43237 | D39: Full sampling | E39: 77a0-613f-ca49 | F39: N | G39: N | H39: N | I39: 1 | J39: 43026 | K39: 9:00AM | L39: GB | M39: 1:1 | N39: 43190 | O39: Eurofins | P39: =SUMIF(Facilities!A:A,"BaystateACPS",Facilities!R:R) -> 26 | Q39: All Results sent | R39: Western | S39: GB, RL
A40: StoughtonPS | B40: STOUGHTON | C40: 43180 | D40: Full sampling | E40: c322-b1d2-a016 | F40: N | G40: N | H40: N | I40: 8 | J40: 43151 | K40: 10:00AM | L40: GB | M40: 8:8 | N40: 43159 | O40: Alpha Analytical | P40: =SUMIF(Facilities!A:A,"StoughtonPS",Facilities!R:R) -> 162 | Q40: All results sent | R40: Southeast | S40: GB
...

Sheet Facilities
A1: Admin Unit | B1: Location | C1: Date Record Updated | D1: PWS ID | E1: PWS | F1: MWRA Lab? | G1: ORG Code | H1: Facility Name | I1: Facilty Type | J1: Status | K1: Sample Plan | L1: Sample Date | M1: # Sample Locations | N1: # Samples | O1: Sampling completed? | P1: Results received? | Q1: Results sent? | R1: total # samples in admin unit | S1: Field CoC Uploaded to Tool | T1: Additional Sample Locations Uploaded to Tool? | U1: Any Pb > AL? (Y/N) | V1: Any Cu > AL? (Y/N) | W1: # FD(P) samples >= Pb AL | X1: # flush samples >= Pb AL | Y1: # FD(P) samples >= Cu AL | Z1: # flush samples >= Cu AL | AA1: Not yet completed | AB1: Staff & Task | AC1: Time estimate to finish | AD1: DEP Region
A2: WestfordPS | B2: WESTFORD | C2: 43174 | D2: 3330000 | E2: N | F2: N | G2: 03260004 | H2: Abbot Elementary School | I2: SCHOOL | J2: A- all done | K2: completed | L2: 43123 | M2: 17 | N2: 32 | O2: Y | P2: Y | Q2: 43160 | S2: Y | T2: Y (1) | U2: Y | V2: N | W2: 3 | X2: 0 | Y2: 0 | Z2: 0
A3: TEC-COOP | B3: EAST WALPOLE | C3: 43217 | D3: 4307000 | E3: N | F3: N | G3: 39020900 | H3: Academy Commonwealth Virtual School | I3: SCHOOL | J3: A- all done | K3: completed | L3: 43217 | M3: 22 | N3: 41 | O3: Y | P3: Y | Q3: 43294 | R3: =SUMIF(A:A,"TEC-COOP",N:N) -> 41 | S3: Y | U3: N | V3: Y | W3: 0 | X3: 0 | Y3: 1 | Z3: 0 | AA3: ORG Code should be 05760000, according to Dan Shovak of The Education Cooperative
A4: AgawamPS | B4: AGAWAM | C4: 43390 | D4: 1005000 | E4: N | F4: N | G4: 00050003 | H4: Agawam Early Childhood Center | I4: SCHOOL | J4: A- all done | K4: completed | L4: 43390 | M4: 14 | N4: 22 | O4: Y | P4: Y | Q4: 43410 | S4: Y | T4: Y | U4: Y | V4: N | W4: 1 | X4: 0 | Y4: 0 | Z4: 0
A5: AgawamPS | B5: AGAWAM | C5: 43393 | D5: 1005000 | E5: N | F5: N | G5: 00050505 | H5: Agawam High School | I5: SCHOOL | J5: A- all done | K5: completed | L5: 43393 | M5: 35 | N5: 68 | O5: Y | P5: Y | Q5: 43420 | S5: Y | U5: Y | V5: N | W5: 1 | X5: 0 | Y5: 0 | Z5: 0
A6: AgawamPS | B6: AGAWAM | C6: 43393 | D6: 1005000 | E6: N | F6: N | G6: 00050405 | H6: Agawam Junior High School | I6: SCHOOL | J6: A- all done | K6: completed | L6: 43393 | M6: 38 | N6: 75 | O6: Y | P6: Y | Q6: 43420 | S6: Y | U6: Y | V6: Y | W6: 6 | X6: 3 | Y6: 1 | Z6: 0
A7: PittsfieldPS | B7: PITTSFIELD | C7: 43258 | D7: 1236000 | E7: N | F7: N | G7: 02360010 | H7: Allendale Elementary School | I7: SCHOOL | J7: A- all done | K7: completed | L7: 43253 | M7: 42 | N7: 69 | O7: Y | P7: Y | Q7: 43299 | S7: Y | U7: Y | V7: N | W7: 0 | X7: 1 | Y7: 0 | Z7: 0
A8: BraintreePS | B8: BRAINTREE | C8: 43266 | D8: 4040000 | E8: N | F8: N | G8: 00400033 | H8: Archie T Morrison Elementary School | I8: SCHOOL | J8: A- all done | K8: completed | L8: 43265 | M8: 72 | N8: 90 | O8: Y | P8: Y | Q8: 43305 | S8: Y | T8: Y | U8: Y | V8: N | W8: 14 | X8: 2 | Y8: 0 | Z8: 0
A9: BaystateACPS | B9: SPRINGFIELD | C9: 43283 | D9: 1281000 | E9: N | F9: N | G9: 35020405 | H9: Baystate Academy Charter Public School | I9: SCHOOL | J9: A- all done | K9: completed | L9: 43190 | M9: 13 | N9: 26 | O9: Y | P9: Y | Q9: 43237 | R9: =SUMIF(A:A,"BaystateACPS",N:N) -> 26 | S9: Y | U9: N | V9: N | W9: 0 | X9: 0 | Y9: 0 | Z9: 0
A10: AgawamPS | B10: AGAWAM | C10: 43392 | D10: 1005000 | E10: N | F10: N | G10: 00050020 | H10: Benjamin J Phelps Elementary School | I10: SCHOOL | J10: A- all done | K10: completed | L10: 43392 | M10: 36 | N10: 69 | O10: Y | P10: Y | Q10: 43420 | S10: Y | U10: Y | V10: N | W10: 1 | X10: 0 | Y10: 0 | Z10: 0
A11: LeominsterPS | B11: LEOMINSTER | C11: 43132 | D11: 2153000 | E11: N | F11: N | G11: 01530003 | H11: Bennett School | I11: SCHOOL | J11: A- all done | K11: completed | L11: 43109 | M11: 7 | N11: 6 | O11: Y | P11: Y | Q11: 43123 | S11: Y | U11: Y | V11: N | W11: 1 | X11: 0 | Y11: 0 | Z11: 0
A12: WestfordPS | B12: WESTFORD | C12: 43174 | D12: 3330000 | E12: N | F12: N | G12: 03260310 | H12: Blanchard Middle School | I12: SCHOOL | J12: A- all done | K12: completed | L12: 43123 | M12: 23 | N12: 35 | O12: Y | P12: Y | Q12: 43160 | S12: Y | U12: N | V12: Y | W12: 0 | X12: 0 | Y12: 1 | Z12: 0
A13: BraintreePS | B13: BRAINTREE | C13: 43266 | D13: 4040000 | E13: N | F13: N | G13: 00400505 | H13: Braintree High School | I13: SCHOOL | J13: A- all done | K13: completed | L13: 43263 | M13: 60 | N13: 103 | O13: Y | P13: Y | Q13: 43305 | S13: Y | U13: Y | V13: Y | W13: 3 | X13: 3 | Y13: 0 | Z13: 1
A14: BRRSD | B14: BRIDGEWATER | C14: 43336 | D14: 4042000 | E14: N | F14: N | G14: 06250320 | H14: Bridgewater Middle School | I14: SCHOOL | J14: A- all done | K14: completed | L14: 43270 | M14: 28 | N14: 50 | O14: Y | P14: Y | Q14: 43334 | S14: Y | U14: Y | V14: Y | W14: 3 | X14: 1 | Y14: 3 | Z14: 1
A15: BRRSD | B15: BRIDGEWATER | C15: 43336 | D15: 4042000 | E15: N | F15: N | G15: 06250505 | H15: Bridgewater-Raynham Regional High School | I15: SCHOOL | J15: A- all done | K15: completed | L15: 43272 | M15: 32 | N15: 55 | O15: Y | P15: Y | Q15: 43334 | S15: Y | U15: Y | V15: Y | W15: 2 | X15: 0 | Y15: 5 | Z15: 1
A16: TantasquaRSD | B16: BRIMFIELD | C16: 43325 | D16: 1043014 | E16: Y | F16: N | G16: 00430005 | H16: Brimfield Elementary School | I16: SCHOOL | J16: A- all done | K16: completed | L16: 43258 | M16: 59 | N16: 92 | O16: Y | P16: Y | Q16: 43325 | S16: Y | U16: Y | V16: N | W16: 1 | X16: 0 | Y16: 0 | Z16: 0
A17: UMassAmherstCEEC | B17: AMHERST | C17: 43146 | D17: 1008000 | E17: N | F17: N | G17: 290857 | H17: Center for Early Education and Care - UMass/Amherst | I17: EECF | J17: A- all done | K17: completed | L17: 43153 | M17: 4 | N17: 7 | O17: Y | P17: Y | Q17: 43160 | R17: =SUMIF(A:A,"UMassAmherstCEEC",N:N) -> 7 | S17: Y | U17: N | V17: N | W17: 0 | X17: 0 | Y17: 0 | Z17: 0
A18: PositiveRegard | B18: HOLYOKE | C18: 43292 | D18: 1137000 | E18: N | F18: N | G18: 01370845 | H18: Center School | I18: SCHOOL | J18: A- all done | K18: completed | L18: 43239 | M18: 9 | N18: 17 | O18: Y | P18: Y | Q18: 43277 | S18: Y | U18: Y | V18: Y | W18: 1 | X18: 1 | Y18: 0 | Z18: 0
A19: NRSD | B19: STOW | C19: 43034 | D19: 2034028 | E19: Y | F19: N | G19: 07250020 | H19: Center School | I19: SCHOOL | J19: A- all done | K19: completed | L19: 43145 | M19: 101 | N19: 136 | O19: Y | P19: Y | Q19: 43175 | S19: Y | U19: N | V19: N | W19: 0 | X19: 0 | Y19: 0 | Z19: 0
A20: WachusettRSD | B20: RUTLAND | C20: 43174 | D20: 2257000 | E20: N | F20: N | G20: 07750310 | H20: Central Tree Middle School | I20: SCHOOL | J20: A- all done | K20: completed | L20: 43132 | M20: 52 | N20: 79 | O20: Y | P20: Y | Q20: 43171 | S20: Y | U20: Y | V20: Y | W20: 7 | X20: 0 | Y20: 1 | Z20: 0
A21: LudlowPS | B21: LUDLOW | C21: 43292 | D21: 1281000 | E21: N | F21: N | G21: 01610020 | H21: Chapin Street Elementary School | I21: SCHOOL | J21: A- all done | K21: completed | L21: 43232 | M21: 49 | N21: 76 | O21: Y | P21: Y | Q21: 43273 | S21: Y | U21: Y | V21: Y | W21: 2 | X21: 1 | Y21: 2 | Z21: 1
A22: WachusettRSD | B22: STERLING | C22: 43146 | D22: 2282000 | E22: N | F22: N | G22: 07750315 | H22: Chocksett Middle School | I22: SCHOOL | J22: A- all done | K22: completed | L22: 43131 | M22: 43 | N22: 76 | O22: Y | P22: Y | Q22: 43171 | S22: Y | U22: Y | V22: Y | W22: 16 | X22: 2 | Y22: 1 | Z22: 1
A23: AgawamPS | B23: AGAWAM | C23: 43384 | D23: 1005000 | E23: N | F23: N | G23: 00050010 | H23: Clifford M Granger Elementary School | I23: SCHOOL | J23: A- all done | K23: completed | L23: 43384 | M23: 59 | N23: 85 | O23: Y | P23: Y | Q23: 43410 | S23: Y | U23: Y | V23: Y | W23: 1 | X23: 0 | Y23: 3 | Z23: 0
A24: ClintonPS | B24: CLINTON | C24: 43292 | D24: 2064000 | E24: N | F24: Y | G24: 00640050 | H24: Clinton Elementary School | I24: SCHOOL | J24: A- all done | K24: completed | L24: 43204 | M24: 140 | N24: 214 | O24: Y | P24: Y | Q24: 43243 | S24: Y | U24: N | V24: N | W24: 0 | X24: 0 | Y24: 0 | Z24: 0
A25: ClintonPS | B25: CLINTON | C25: 43292 | D25: 2064000 | E25: N | F25: Y | G25: 00640305 | H25: Clinton Middle School | I25: SCHOOL | J25: A- all done | K25: completed | L25: 43204 | M25: 42 | N25: 41 | O25: Y | P25: Y | Q25: 43243 | S25: Y | U25: Y | V25: N | W25: 2 | X25: 0 | Y25: 0 | Z25: 0
A26: ClintonPS | B26: CLINTON | C26: 43292 | D26: 2064000 | E26: N | F26: Y | G26: 00640505 | H26: Clinton Senior High School | I26: SCHOOL | J26: A- all done | K26: completed | L26: 43214 | M26: 37 | N26: 59 | O26: Y | P26: Y | Q26: 43243 | R26: =SUMIF(A:A,"ClintonPS",N:N) -> 314 | S26: Y | U26: N | V26: N | W26: 0 | X26: 0 | Y26: 0 | Z26: 0
A27: WestfordPS | B27: WESTFORD | C27: 43182 | D27: 3330000 | E27: N | F27: N | G27: 03260025 | H27: Col. John Robinson School | I27: SCHOOL | J27: A- all done | K27: completed | L27: 43124 | M27: 53 | N27: 74 | O27: Y | P27: Y | Q27: 43160 | S27: Y | U27: Y | V27: N | W27: 6 | X27: 0 | Y27: 0 | Z27: 0
A28: HaverhillComAct | B28: NEWBURYPORT | C28: 43266 | D28: 3206000 | E28: N | F28: N | G28: 290769 | H28: Community Action Headstart at Newburyport | I28: EECF | J28: A- all done | K28: completed | L28: 43242 | M28: 6 | N28: 11 | O28: Y | P28: Y | Q28: 43265 | R28: =SUMIF(A:A,"HaverhillComAct",N:N) -> 59 | S28: Y | U28: N | V28: N | W28: 0 | X28: 0 | Y28: 0 | Z28: 0
A29: HaverhillComAct | B29: HAVERHILL | C29: 43266 | D29: 3128000 | E29: N | F29: N | G29: 200704 | H29: Community Action Headstart Fox Center | I29: EECF | J29: A- all done | K29: completed | L29: 43242 | M29: 20 | N29: 36 | O29: Y | P29: Y | Q29: 43265 | S29: Y | U29: N | V29: N | W29: 0 | X29: 0 | Y29: 0 | Z29: 0
A30: HaverhillComAct | B30: HAVERHILL | C30: 43266 | D30: 3128000 | E30: N | F30: N | G30: 212295 | H30: Community Action Headstart-Goldman Center | I30: EECF | J30: A- all done | K30: completed | L30: 43242 | M30: 6 | N30: =M30*2 -> 12 | O30: Y | P30: Y | Q30: 43265 | S30: Y | U30: N | V30: N | W30: 0 | X30: 0 | Y30: 0 | Z30: 0
A31: PittsfieldPS | B31: PITTSFIELD | C31: 43280 | D31: 1236000 | E31: N | F31: N | G31: 02360065 | H31: Crosby Elementary School | I31: SCHOOL | J31: A- all done | K31: completed | L31: 43246 | M31: 23 | N31: 46 | O31: Y | P31: Y | Q31: 43280 | S31: Y | U31: Y | V31: N | W31: 2 | X31: 0 | Y31: 0 | Z31: 0
A32: SEBRSD | B32: SPENCER | C32: 43259 | D32: 2280000 | E32: N | F32: N | G32: 07670505 | H32: David Prouty High School | I32: SCHOOL | J32: A- all done | K32: completed | L32: 43241 | M32: 14 | N32: 21 | O32: Y | P32: Y | Q32: 43259 | S32: Y | U32: N | V32: Y | W32: 0 | X32: 0 | Y32: 1 | Z32: 0
A33: WachusettRSD | B33: HOLDEN | C33: 43137 | D33: 2134000 | E33: N | F33: N | G33: 07750018 | H33: Davis Hill Elementary School | I33: SCHOOL | J33: A- all done | K33: completed | L33: 43137 | M33: 84 | N33: 133 | O33: Y | P33: Y | Q33: 43160 | S33: Y | T33: Y (4) | U33: Y | V33: Y | W33: 7 | X33: 0 | Y33: 14 | Z33: 2 | AA33: Initial datafile errors; resent 3/8
A34: WachusettRSD | B34: HOLDEN | C34: 43160 | D34: 2134000 | E34: N | F34: N | G34: 07750020 | H34: Dawson Elementary School | I34: SCHOOL | J34: A- all done | K34: completed | L34: 43133 | M34: 69 | N34: 104 | O34: Y | P34: Y | Q34: 43146 | S34: Y | U34: Y | V34: N | W34: 3 | X34: 0 | Y34: 0 | Z34: 0
A35: BraintreePS | B35: BRAINTREE | C35: 43266 | D35: 4040000 | E35: N | F35: N | G35: 00400050 | H35: Donald Ross Elementary School | I35: SCHOOL | J35: A- all done | K35: completed | L35: 43265 | M35: 38 | N35: 59 | O35: Y | P35: Y | Q35: 43305 | S35: Y | U35: Y | V35: N | W35: 4 | X35: 0 | Y35: 0 | Z35: 0
A36: North ReadingPS | B36: NORTH READING | C36: 43292 | D36: 3213000 | E36: N | F36: N | G36: 02170003 | H36: E Ethel Little Elementary School | I36: SCHOOL | J36: A- all done | K36: completed | L36: 43252 | M36: 39 | N36: 75 | O36: Y | P36: Y | Q36: 43273 | S36: Y | U36: Y | V36: N | W36: 1 | X36: 0 | Y36: 0 | Z36: 0
A37: WachusettRSD | B37: JEFFERSON | C37: 43174 | D37: 2134000 | E37: N | F37: N | G37: 07750001 | H37: Early Childhood Center | I37: EECF | J37: A- all done | K37: completed | L37: 43132 | M37: 18 | N37: 29 | O37: Y | P37: Y | Q37: 43146 | S37: Y | U37: Y | V37: Y | W37: 5 | X37: 0 | Y37: 5 | Z37: 1
A38: SEBRSD | B38: SPENCER | C38: 43273 | D38: 2280000 | E38: N | F38: N | G38: 07670008 | H38: East Brookfield Elementary School | I38: SCHOOL | J38: A- all done | K38: completed | L38: 43244 | M38: 52 | N38: 84 | O38: Y | P38: Y | Q38: 43273 | S38: Y | U38: N | V38: N | W38: 0 | X38: 0 | Y38: 0 | Z38: 0
A39: BraintreePS | B39: BRAINTREE | C39: 43266 | D39: 4040000 | E39: N | F39: N | G39: 00400305 | H39: East Middle School | I39: SCHOOL | J39: A- all done | K39: completed | L39: 43264 | M39: 19 | N39: 28 | O39: Y | P39: Y | Q39: 43305 | S39: Y | U39: N | V39: N | W39: 0 | X39: 0 | Y39: 0 | Z39: 0
A40: LudlowPS | B40: LUDLOW | C40: 43273 | D40: 1281000 | E40: N | F40: N | G40: 01610010 | H40: East Street Elementary School | I40: SCHOOL | J40: A- all done | K40: completed | L40: 43218 | M40: 86 | N40: 131 | O40: Y | P40: Y | Q40: 43273 | S40: Y | U40: Y | V40: Y | W40: 2 | X40: 0 | Y40: 2 | Z40: 0
...

Sheet Contacts
A1: Date Record Updated | B1: Notes | C1: Admin Unit | D1: Location | E1: PPC First Name | F1: PPC Last Name | G1: PPC Title | H1: PPC Phone | I1: PPC Address | J1: PPC Email | K1: Municipal Official | L1: PWS Contact | M1: Regional DEP Contact | N1: TAP Email | O1: Facility Personnel
A2: 43088 | B2: Spoke on phone | C2: AbingtonPS | D2: ABINGTON | E2: Jason | F2: Linn | G2: Maintenance Director | H2: 781-982-2154 | I2: 1071 Washington St., Abington, MA 02351 | J2: jasonlinn@abingtonps.org | K2: rlafond@abingtonma.gov | L2: dcallahan@abrockwater.com | M2: Richard.Rondeau@state.ma.us | N2: rlarson@umass.edu
A3: 43259 | B3: Rick spoke w/ Doug White | C3: AgawamPS | D3: AGAWAM | E3: Steve | F3: Lemanski | G3: Superintendent of Schools | H3: 413-821-0552 | I3: 1305 Springfield St., Feeding Hills, MA 01030 | J3: slemanski@agawamed.org | K3: mayor@agawam.ma.us | L3: cgolba@agawam.ma.us | M3: Deirdre.Doherty@state.ma.us | N3: robert.hoyt@state.ma.us | O3: Norm, Robbins, Principal, nrobbins@agawamed.org |Cheryl, Salomeo, Principal, csalomeo@agawamed.org |Susan, Federico, Principal, sfederico@agawamed.org |Shelley, Russell, Principal, srussell@agawamed.org |Noelle, Colbert, Principal, ncolbert@agawamed.org |Thomas , Schnepp, Principal, tschnepp@agawamed.org |Robin, Fernandes, Director, rfernandes@agawamed.org |
A4: 43243 | B4: Waiting List | C4: Amesbury PS | D4: AMESBURY | E4: Joan | F4: Liporto | G4: Director of Finance and Operations | H4: 978-388-0507 x7019 | I4: 5 Highland Street, Amesbury, MA 01915 | J4: liportoj@amesburyma.gov | K4: asked for email address | L4: masonj@amesburyma.gov | M4: Thomas.Mahin@state.ma.us | O4: Norman, Fredette, Facilities Manager, fredetten@amesburyma.gov |
A5: 43237 | B5: All Results sent | C5: BaystateACPS | D5: SPRINGFIELD | E5: Tim | F5: Sneed | G5: Executive Director | H5: 413-366-5103 | I5: 2001 Roosevelt Ave., Springfield, MA 01104 | J5: tsneed@bacps.net | K5: msarno@springfieldcityhall.com | L5: josh.schimmel@waterandsewer.org | M5: Deirdre.Doherty@state.ma.us | N5: rlarson@umass.edu | O5: Tim, Sneed, Executive Director, tsneed@bacps.net | Isabel, Cartagena, Business Manager, icartagena@bacps.net |
A6: 43229 | B6: IM completed | C6: BraintreePS | D6: BRAINTREE | E6: Edward | F6: Cronin | G6: Director of Finance and Operations | H6: 781-794-8482 | I6: 348 Pond St., Braintree, MA 02184 | J6: ecronin@braintreema.gov | K6: mayorsoffice@braintreema.gov | L6: ldutton@braintreema.gov | M6: Richard.Rondeau@state.ma.us | N6: yaskmenow1983@gmail.com | O6: Edward, Cronin, Director of Finance and Operations, ecronin@braintreema.gov |
A7: 43209 | B7: IM completed | C7: BRRSD | D7: BRIDGEWATER | E7: Paul | F7: Fox | G7: Director of Facilities | H7: 508-279-2140 | I7: 166 Mt Prospect St., Bridgewater, MA 02324 | J7: pfoxjr@bridge-rayn.org | K7: TownManager@bridgewaterma.org | L7: wmwardrcwd@comcast.net/jkazlauskas@bridgewaterma.org | M7: Richard.Rondeau@state.ma.us | N7: tombienk58@gmail.com | O7: Paul, Fox, Director of Facilities, pfoxjr@bridge-rayn.org |
A8: 43217 | B8: Out of Program | C8: Canton Preschool | D8: CANTON | E8: Katrina | F8: Selawsky | G8: Director | H8: 781-828-4800 | I8: 3 Blue Hill River Road, Canton, MA 02021 | J8: info@learningcirclepreschool.org | K8: bos@town.canton.ma.us | L8: mtrotta@town.canton.ma.us | M8: Richard.Rondeau@state.ma.us | N8: out of program | O8: Katrina, Selawsky, Director, info@learningcirclepreschool.org |
A9: 43230 | B9: Out of Program | C9: CCCDP | D9: HYANNIS | E9: Michael | F9: Scarpellini | G9: Director of Youth and Support Services | H9: 508-775-6240 | I9: 83 Pearl St., Hyannis, MA 02601 | J9: mscarpellini@cccdp.org | K9: email@town.barnstable.ma.us,townmanager@falmouthmass.us | L9: hans.keijser@town.barnstable.ma.us | M9: Richard.Rondeau@state.ma.us | N9: tombienk58@gmail.com | O9: Michael, Scarpellini, Director , mscarpellini@cccdp.org |
A10: 43220 | B10: IM scheduled | C10: Children's Workshop | D10: CUMBERLAND RI | E10: Nicole | F10: Chiello | G10: VP, Regional Director of Operations | H10: 401-580-7738 | I10: 45 Industrial Road | J10: nchiello@childrensworkshop.com | K10: selectmen@town.westborough.ma.us | L10: wparks@wbridgewater.com | M10: Richard.Rondeau@state.ma.us | N10: yaskmenow1983@gmail.com,tombienk58@gmail.com> | O10: Amanda, Miller, Director, wbridgewater@childrensworkshop.com |
A11: 43243 | B11: All Results sent | C11: ClintonPS | D11: CLINTON | E11: Russell | F11: Karlstad | G11: Director of Public Facilities | H11: 978-365-4114 | I11: 242 Church Street, Cinton, MA 01510 | J11: rkarlstad@clintonma.gov | K11: mward@clintonma.gov | L11: cmcgown@clintonma.gov | M11: Robert.Bostwick@state.ma.us | N11: llaine911@gmail.com | O11: Russell, Karlstad, Director of Public Facilities, rkarlstad@clintonma.gov |
A12: 43102 | B12: Follow Up | C12: Dracut | D12: DRACUT
A13: 43186 | B13: All Results sent | C13: GraftonPS | D13: GRAFTON | E13: Anthony | F13: LeMay | G13: Director of Buildings and Grounds | H13: 508-735-2166 | I13: 30 Providence Rd, Grafton, MA 01519 | J13: lemaya@grafton.k12.ma.us | K13: mcinerneyt@grafton-ma.gov | L13: graftonh20@aol.com | M13: Robert.Bostwick@state.ma.us | N13: llaine911@gmail.com | O13: Anthony, Lemay, Director of Buildings and Grounds, lemaya@grafton.k12.ma.us |
A14: 43243 | B14: Sampling completed | C14: HaverhillComAct | D14: HAVERHILL | E14: Jill | F14: Sullivan | G14: Operations Manager | H14: 978-372-5052 x447 | I14: 75 Elm St., Haverhill, MA 01830 | J14: jsullivan@communityactioninc.org | K14: mayor@cityofhaverhill.com | L14: rward@haverhillwater.com | M14: Thomas.Mahin@state.ma.us | N14: yaskmenow1983@gmail.com | O14: Jill, Sullivan, Operations Manager, jsullivan@communityactioninc.org | Kerry Perry, kperry@communityactioninc.org
A15: 43403 | B15: Providing TA for sample plan | C15: HopkintonPS | D15: Hopkinton | E15: Susan | F15: Rothermich | G15: Director of Finance and Operations | H15: (508) 417-9385 | I15: 89 Hayden Rowe Street, Hopkinton, MA 01748 | J15: srothermich@hopkinton.k12.ma.us
A16: 43052 | B16: All Results sent | C16: LeominsterPS | D16: LEOMINSTER | E16: Anthony | F16: Sciabarrasi | G16: Facility Director | H16: 978 534 7700 x 332 | I16: 24 Church St., Leominster, MA 01453 | J16: anthony.sciabarrasi@leominster.mec.edu | K16: dmazzarella@leominster-ma.gov | L16: robert.chalifoux@veolia.com | M16: Robert.Bostwick@state.ma.us | N16: yaskmenow1983@gmail.com | O16: anthony, sciabarrasi, facility director, anthony.sciabarrasi@leominster.mec.edu |
A17: 43243 | B17: Sample plans completed | C17: Little Folks | D17: EAST BOSTON | E17: Marie | F17: Bossi | G17: Executive Director | H17: 617-569-0294 | I17: 65 Trenton Street | J17: little.folks@aol.com | K17: mayor@cityofboston.gov | L17: sullivanjp@bwsc.org | M17: Thomas.Mahin@state.ma.us | N17: robert.hoyt@state.ma.us | O17: Marie, Bossi, Executive Director, little.folks@aol.com | Michelle, Gill, Education Supervisor, little.folks@aol.com |
A18: 43222 | B18: Sent ack. Email | C18: LongmeadowPS | D18: LONGMEADOW | E18: John | F18: Cloonan | G18: Facilities Director - Town of Longmeadow | H18: 413-567-3400 | I18: 31 Pondside Rd, Longmeadow, MA 01106 | J18: jcloonan@longmeadow.org | K18: Townhall@longmeadow.org | L18: pthurber@longmeadow.org | M18: Deirdre.Doherty@state.ma.us | O18: Todd , Carney, Facilities Foreman, tcarney@longmeadow.k12.ma.us |
A19: 43234 | B19: Sampling completed | C19: LudlowPS | D19: LUDLOW | E19: Darlene | F19: Cincone | G19: Dir. of Oper./Asst, Business Mgr. | H19: 413-583-5663 ext 106 | I19: 63 Chestnut St., Ludlow, MA 01056 | J19: d_cincone@ludlowps.org | K19: selectmen@Ludlow.ma.us | L19: josh.schimmel@waterandsewer.org | M19: Deirdre.Doherty@state.ma.us | N19: vdkiken@comcast.net | O19: Michael, Bertini, District Facilities Coordinator, m_bertini@ludlowps.org |
A20: 43255 | B20: Sampling completed | C20: LunenburgPS | D20: LUNENBURG | E20: John | F20: Londa | G20: Director of Facilities | H20: 978-230-2351 | I20: 1025 Mass. Ave., Lunenburg, MA 01462 | J20: jlonda@lunenburgonline.com | K20: bos@lists.lunenburgonline.com | L20: FMcNamara@Lunenburgwater.net | M20: Robert.Bostwick@state.ma.us | N20: yaskmenow1983@gmail.com | O20: John, Londa, Director of Facilities, jlonda@lunenburgonline.com |
A21: 43230 | B21: Sampling scheduled | C21: LynnfieldPS | D21: LYNNFIELD | E21: Anthony | F21: Fratoni | G21: Assistant Director of School Operations | H21: 781-334-9501 | I21: 55 Summer St., Lynnfield, MA 01940 | J21: tfratoni@town.lynnfield.ma.us | K21: (781) 334-9400 | L21: jfinegan@lwdma.us | M21: Thomas.Mahin@state.ma.us | N21: yaskmenow1983@gmail.com | O21: Steve , DeBettencourt, Assistant Director of Facilities, sdebettencourt@town.lynnfield.ma.us |
A22: 43048 | B22: All Results sent | C22: MansfieldPS | D22: MANSFIELD | E22: Edward | F22: Donoghue | G22: Asst. Superintendent for Finance & Operations | H22: 505-261-7506 | I22: 2 Park Row, Mansfield, MA 02048 | J22: edward.donoghue@mansfieldschools.com | K22: townmanager@mansfieldma.com | L22: kgaffney@mansfieldma.com | M22: Richard.Rondeau@state.ma.us | N22: yaskmenow1983@gmail.com | O22: Matthew, Jacques, Director of Facilities, matthew.jacques@mansfieldschools.com |
A23: 43241 | B23: IM scheduled | C23: MasconometRSD | D23: BOXFORD | E23: Douglas | F23: Batchelder | G23: Director of Operations | H23: 978-423-8390 | I23: 20 Endicott Rd, Boxford, MA 01921 | J23: dbatchelder@masconomet.org | K23: abenson@town.boxford.ma.us | L23: none | M23: Thomas.Mahin@state.ma.us | N23: robert.hoyt@state.ma.us | O23: Douglas, Batchelder, Director of Operations, dbatchelder@masconomet.org |
A24: 43336 | B24: Rick spoke w/ Tim Goulding | C24: MaynardPS | D24: MAYNARD | E24: Aaron | F24: Miklosko | G24: Director of Public Works | H24: 978-897-1308 | I24: 195 Main Street, Maynard, MA 01754 | J24: amiklosko@townofmaynard.net | K24: AScribner@townofmaynard.net | L24: amiklosko@townofmaynard.net | M24: Robert.Bostwick@state.ma.us | O24: Aaron, Miklosko, Director of Public Works, amiklosko@townofmaynard.net |
A25: 43217 | B25: Out of Program | C25: MillisPS | D25: MILLIS | E25: John | F25: Engler | G25: Director of Operations | H25: 508-376-7013 | I25: 245 Plain St., Millis, MA 02054 | J25: jengler@millisps.org | K25: kbouret@millis.net | L25: jmckay@millis.net | M25: Robert.Bostwick@state.ma.us | O25: John, Engler, Facilities Director, jengler@millisps.org |
A26: 43249 | B26: Ready to schedule IM, emailed him a reminder | C26: NarragansetRSD | D26: BALDWINVILLE | E26: Rick | F26: Moulton | G26: Director of Buildings and Grounds | H26: 978-895-9381 | I26: 462 Baldwinville Rd, Baldwinville, MA 01436 | J26: rmoulton@nrsd.org | K26: townadministrator@templeton1.org | L26: rdavan@templetonlight.com | M26: Robert.Bostwick@state.ma.us | O26: Rick, Moulton, Facilities Director NRSD, rmoulton@nrsd.org |
A27: 42990 | B27: All Results sent | C27: NashValTSD | D27: WESTFORD | E27: Jeanne | F27: Savoie | G27: Business Manager | H27: 978-692-4711 x 11174 | I27: 100 Littleton Rd, Westford, MA 01886 | J27: jsavoie@nashobatech.net | K27: jross@westfordma.gov | L27: scronin@westfordma.gov | M27: Thomas.Mahin@state.ma.us | N27: yaskmenow1983@gmail.com | O27: Jeanne, Savoie, Business Manager, jsavoie@nashobatech.net | Paul, Jussaume, Director of Vocational Operations/Facilities, pjussaume@nashobatech.net |
A28: 43243 | B28: Waiting List | C28: NMRSD | D28: PEPPERELL | E28: Andrea | F28: Royer | G28: Secretary | H28: 978-743-4986 | I28: 45 Main Street, Pepperell, MA 01463 | J28: aroyer@nmrsd.org | K28: mandrews@town.pepperell.ma.us | L28: jjordan@town.pepperell.ma.us | M28: Robert.Bostwick@state.ma.us | O28: Al, Beauchemin, Day Lead Custodian, abeauchemin@nmrsd.org | Rich, Carlson, Maintenance, rcarlson@nmrsd.org |
A29: 43255 | B29: Sampling completed | C29: North ReadingPS | D29: NORTH READING | E29: Wayne | F29: Hardacker | G29: Supervisor of Buildings & Grounds | H29: 978-360-1687 | I29: 189 Park St., North Reading, MA 01864 | J29: whardacker@nrpsk12.org | K29: mgilleberto@northreadingma.gov | L29: mclark@northreadingma.gov | M29: Thomas.Mahin@state.ma.us | N29: yaskmenow1983@gmail.com | O29: Wayne, Hardacker, Supervisor of Buildings & Grounds, whardacker@nrpsk12.org |
A30: 43082 | B30: All Results sent | C30: NRSD | D30: BOLTON | E30: Robert | F30: Frieswick | G30: Interim Facilities Manager | H30: 978-779-0539 | I30: 50 Mechanic St., Bolton, MA 01740 | J30: rfrieswick@nrsd.net | K30: rczekanski@townofbolton.biz | L30: JCONVERSE@NRSD.NET | M30: Robert.Bostwick@state.ma.us | N30: yaskmenow1983@gmail.com | O30: Robert , Freiswick, Interim Facilities Manager, rfreiswick@nrsd.net | Patricia, Marone, Interim Business and Operations Manager, pmarone@nrsd.net |
A31: 43210 | B31: All Results sent | C31: NSWSD | D31: NEW SALEM | E31: Larry | F31: Ramsdell | G31: Director of Maintenance | H31: 978-544-6926 | I31: 201 Wendell Rd, New Salem, MA 01355 | J31: ramsdell@swiftriverschool.org | K31: towncoord@crocker.com | L31: ramsdell@swiftriverschool.org | M31: Deirdre.Doherty@state.ma.us | N31: vdkiken@comcast.net | O31: Larry, Ramsdell, Director of Maintenance, ramsdell@swiftriverschool.org |
A32: 43255 | B32: Sampling completed | C32: PittsfieldPS | D32: PITTSFIELD | E32: James | F32: Esoldi | G32: LEA / Project Supervisor | H32: 413-281-3158 | I32: 81 Hawthorne Ave., Pittsfield, MA 01201 | J32: jesoldi@cityofpittsfield.org | K32: mayorsoffice@pittsfieldch.com | L32: bstack@cityofpittsfield.org | M32: Deirdre.Doherty@state.ma.us | N32: vdkiken@comcast.net | O32: James, Esoldi, LEA/Project Suprevisor, jesoldi@cityofpittsfield.org |
A33: 43234 | B33: Sampling scheduled | C33: PositiveRegard | D33: HOLYOKE | E33: Peter | F33: Miller | G33: Director of Administrative Operations | H33: 413-533-9500 | I33: 1913 Northampton St., Holyoke, MA 01040 | J33: pmiller@positiveregard.com | K33: morsea@holyoke.org | L33: contid@holyoke.org | M33: Deirdre.Doherty@state.ma.us | N33: vdkiken@comcast.net | O33: Peter, Miller, Director of Administrative Operations, pmiller@positiveregard.com |
A34: 43234 | B34: Out of Program | C34: RandolphPS | D34: RANDOLPH | E34: Richard | F34: Brewer | G34: DPW Superintendent | H34: 781-961-0942 | I34: 41 S. Main St., Randolph, MA 02368 | J34: rbrewer@randolph-ma.gov | K34: dmurphy@randolph-ma.gov | L34: rbrewer@randolph-ma.gov | M34: Richard.Rondeau@state.ma.us | O34: Mike, Caliri, Maintenance Director, calirim@randolph.ma.gov |
A35: 43014 | B35: Rick helped with Tool | C35: ReadingPS | D35: READING | E35: Erik | F35: Mysliwy | G35: Water Quality and Supply Coordinator | H35: 781-858-2566 | I35: 16 Lowell St., Reading, MA 01867 | J35: emysliwy@ci.reading.ma.us | K35: townmanager@ci.reading.ma.us | L35: jzager@ci.reading.ma.us | M35: Thomas.Mahin@state.ma.us | N35: rlarson@umass.edu | O35: Erik, Mysliwy, Water Quality & Supply Coordinator, emysliwy@ci.reading.ma.us |
A36: 43055 | B36: Spoke w/ Martelli, they sampled already w/ MWRA | C36: ReverePS | D36: REVERE | E36: Carl | F36: Svendsen | G36: Director of Plant and Maintenance | H36: 781-286-8226 | I36: 101 School St., Revere, MA 02151 | J36: csvendsen@revere.mec.edu | K36: revere_mayor@revere.org | L36: mamartelli@revere.org | M36: Thomas.Mahin@state.ma.us | N36: rlarson@umass.edu | O36: Carl, Svendsen, Director of Maintenance and Facilities, csvendsen@revere.mec.edu |
A37: 43230 | B37: IM completed | C37: SBRSD | D37: SHEFFIELD | E37: Jeremy | F37: Wells | G37: Director of Buildings, Grounds, and Food Services | H37: 413-229-8778 x 158 | I37: 491 Berkshire School Road, Sheffield, MA 01257 | J37: jwells@sbrsd.org | K37: rlabombard@sheffieldma.gov | L37: Travis Helming | M37: Deirdre.Doherty@state.ma.us | N37: vdkiken@comcast.net | O37: Jeremy , Wells, Director of Buildings and Grounds , jwells@sbrsd.org |
A38: 43201 | B38: IM completed | C38: SEBRSD | D38: SPENCER | E38: Eric | F38: Hevy | G38: Supervisor Buildings & Grounds | H38: 508-885-8500 x9 | I38: 306 Main St., Spencer, MA 01562 | J38: hevye@sebrsd.org | K38: tpepe@spencerma.gov | L38: gkarpowicz@spencerma.gov | M38: Robert.Bostwick@state.ma.us | N38: llaine911@gmail.com | O38: Eric, Hevey, Supervisor Buildings & Grounds, heveye@sebrsd.org |Gary Suter, Business Director, suterg@sebrsd.or
A39: 43223 | B39: IM scheduled | C39: SelfHelp | D39: BROCKTON | E39: Frances | F39: Reid | G39: ERSEA/Ancillary Services Manager | H39: 508-587-1716 | I39: 370 Howard Street, Brockton, MA 02302 | J39: freid@selfhelpinc.org | K39: BillCarpenter@cobma.us | L39: michael.sessine@veolia.com | M39: Richard.Rondeau@state.ma.us | N39: yaskmenow1983@gmail.com | O39: Frances, Freid, ERSEA/Ancillary Services Manager, freid@selfhelpinc.org |
A40: 43235 | B40: IM scheduled | C40: Shutesbury ES | D40: SHUTESBURY | E40: Jacqueline | F40: Mendonsa | G40: Principal | H40: 413-259-1212 x 111 | I40: 23 West Pelham Rd, Shutesbury, MA 01072 | J40: mendonsaj@shutesburyschool.org | K40: townadmin@shutesbury.org | L40: Robert Mahler | M40: Deirdre.Doherty@state.ma.us | N40: tobiason | O40: Matthew, Foster, Head Custodian, fosterm@shutesburyschool.org |
...

Sheet Stats
B1: 2017-2018 Statistics | E1: Assistance
B2: Number of facilities w/ results | C2: =COUNTIFS(Facilities!P:P,"<>",Facilities!P:P,"<>Out of Program")-1 -> 174 | E2: Full sampling | F2: =COUNTIF('Admin Unit'!D:D,"Full sampling") -> 42
B3: Number of facilities w/ sample plans | C3: =COUNTIF(Facilities!K:K,"Completed") -> 174 | E3: Follow up | F3: =COUNTIF('Admin Unit'!D:D,"Follow up") -> 5
B4: Number of facilities applied to program | C4: =COUNTIF(Facilities!$K$2:$K$240,"<>"&"Out of Program") -> 200 | E4: None | F4: =COUNTIF('Admin Unit'!D:D,"None") -> 0
B5: Number of facilities done sampling | C5: =COUNTIF(Facilities!L:L,"<="&TODAY()) -> 174 | E5: EECF | F5: =COUNTIF(Facilities!I:I,"EECF") -> 37
B6: Average number of samples/facility | C6: =AVERAGE(Facilities!$N$2:$N$240) -> 68.931034 | E6: No response | F6: =COUNTIF('Admin Unit'!D2:D60,"") -> 0
B7: Maximum number of samples/ facility | C7: =MAX(Facilities!$N$2:$N$240) -> 214 | E7: Out of program | F7: =COUNTIF('Admin Unit'!D2:D60,"Out of program") -> 8
B8: Minimum number of samples/ facility | C8: =MIN(Facilities!$N$2:$N$240) -> 6 | E8: Total | F8: =COUNTIF('Admin Unit'!A:A,"<>")-1 -> 59
B9: Total number of samples | C9: =SUM(Facilities!$N$2:$N$240) -> 11994
B10: Total number of samples taken so far | C10: =SUMIF(Facilities!O:O,"Y",Facilities!N:N) -> 11994 | E10: Districts
B11: Number of samples analyzed by MWRA | C11: 607 | E11: IM completed | F11: =COUNTIF('Admin Unit'!J:J,"<="&TODAY()) -> 39
B12: Number of samples paid for by UMass | C12: =C10-C11 -> 11387 | E12: IM scheduled | F12: =COUNTIF('Admin Unit'!J:J,">"&TODAY()) -> 0
E14: Facilities
E15: PWS | F15: =COUNTIF(Facilities!E:E,"Y") -> 14
E16: MWRA | F16: =COUNTIF(Facilities!F:F,"Y") -> 23
B17: 2016-2017 Satistics | E17: Sampling Plan | F17: =COUNTIF(Facilities!K:K,"Completed") -> 174
B18: Number of schools w/ sample plans | C18: 817 | E18: Sampling done | F18: =COUNTIF(Facilities!L:L,"<="&TODAY()) -> 174 | G18: =COUNTIF(Facilities!O:O,"Y") -> 174
B19: Number of schools in program | C19: 894 | E19: Sampling Date | F19: =COUNTIF(Facilities!L:L,"<>")-COUNTIF(Facilities!L:L,"Out of Program")-1 -> 174
B20: Number of schools done sampling | C20: 818 | E20: sample plan, not sampled yet | F20: =COUNTIFS(Facilities!K:K,"Completed",Facilities!L:L,"") -> 0 | I20: Phase 1 | J20: Phase 1 | L20: Total | M20: %
B21: Number of schools w/ results | C21: 817 | E21: Results Sent | F21: =COUNTIFS(Facilities!Q:Q,"<>",Facilities!Q:Q,"<>Out of Program")-1 -> 174 | J21: 818 | L21: =F21+J21 -> 992
B22: Average number of samples/school | C22: 68.944513 | E22: Facilities >Pb | F22: =COUNTIF(Facilities!U:U,"Y") -> 108 | G22: =F22/$F$21 -> 0.62068966
B23: Minimum number of samples/ school | C23: 2 | E23: Facilities >Cu | F23: =COUNTIF(Facilities!V:V,"Y") -> 67 | G23: =F23/$F$21 -> 0.38505747
B24: Maximum number of samples/ school | C24: 431 | E24: Facilities 0 exceedance | F24: =COUNTIFS(Facilities!U:U,"N",Facilities!V:V,"N") -> 51 | G24: =F24/$F$21 -> 0.29310345 | I24: 28 | J24: =I24/100*$J$21 -> 229.04 | L24: =F24+J24 -> 280.04 | M24: =L24/$L$21*100 -> 28.229839 | P24: Pase 1 | Q24: Phase 2 | R24: Overall
B25: Total number of samples paid by UMass | C25: 50396 | O25: Pb only | P25: 40 | Q25: 32 | R25: 38.6
B26: Total number of samples | C26: 55914 | O26: Cu only | P26: 3 | Q26: 9 | R26: 4
E27: lead only | F27: 56 | G27: =F27/$F$21 -> 0.32183908 | I27: 40 | J27: =I27/100*$J$21 -> 327.2 | L27: =F27+J27 -> 383.2 | M27: =L27/$L$21*100 -> 38.629032 | O27: Pb & Cu | P27: 29 | Q27: 30 | R27: 29.2
E28: both >Als | F28: 52 | G28: =F28/$F$21 -> 0.29885057 | I28: 29 | J28: =I28/100*$J$21 -> 237.22 | L28: =F28+J28 -> 289.22 | M28: =L28/$L$21*100 -> 29.155242 | O28: neither | P28: 28 | Q28: 29 | R28: 28.3
E29: copper only | F29: 15 | G29: =F29/$F$21 -> 0.086206897 | I29: 3 | J29: =I29/100*$J$21 -> 24.54 | L29: =F29+J29 -> 39.54 | M29: =L29/$L$21*100 -> 3.9858871
E32: # Towns | F32: =SUMPRODUCT(1/COUNTIF(Facilities!B2:B240,Facilities!B2:B240)) -> 81
P35: Pb(P) | Q35: Pb(%)
O36: <or= 1 ppb | P36: 42.4 | Q36: 68.5
O37: 1 to 15 ppb | P37: 47.1 | Q37: 29.4
O38: > 15 ppb | P38: 10.5 | Q38: 2.1
