Workbook

Sheet Dropdowns
A1: Phase | B1: Program | C1: Lab | D1: TAP | E1: Status | F1: DEP Region | G1: Completion level | H1: Completion Notes
A2: 1 | B2: EAP | C2: MRWA | D2: Gene | E2: 1-Not Contacted Yet | F2: NERO | G2: No Detect, Done | H2: Plan to resample
A3: 2 | B3: SWIG | C3: Alpha | D3: Katie | E3: 2-Contacted | F3: CERO | G3: Follow-up | H3: Follow-up testing
A4: 3 | C4: Barnstable | D4: Rick | E4: 3-Has Responded | F4: SERO | G4: Remediation | H4: Communicate w/ parents
C5: Con-Test | D5: ? | E5: 3.5-On Hold | F5: WERO | G5: Replacement | H5: Issue do not drink order
C6: Granite | D6: ? | E6: 4-Sample Plan Done | G6: No response | H6: Provide water bottles
C7: RI Analytical | E7: 5-Sampling Scheduled | H7: Provide bottled water
E8: 6-Sampling Done | H8: Put fountains out of commission
E9: 7-Results Received | H9: Routine maintenance
E10: 8-Results Sent | H10: Routine flushing
E11: 9-Completed | H11: Turn off contaminated outlets
E12: 0-Out of Program | H12: Replace fixtures
H13: Replace internal piping
H14: Other

Sheet Out of Program
A1: Date Record Updated | B1: UMass Status | C1: Date of DEP Decision | D1: DEP Decision | E1: Application Date & Time | F1: Code from Application Form | G1: Facility Name | H1: Facility Type | I1: Facility Street 1 | J1: Facility Street 2 | K1: Facility Town | L1: Facility Zip | M1: PPC First Name | N1: PPC Last Name | O1: PPC Job Title | P1: PPC Phone | Q1: PPC Email | R1: PPC Street 1 | S1: PPC Street 2 | T1: PPC Town | U1: PPC Zip | V1: Construction year | W1: Future Operations | X1: Registered Name (EEC) if different than Col G | Y1: Report Tool Pin | Z1: Org Code | AA1: TAP Name | AB1: Sampler Name | AC1: Sampling Date | AD1: # First Draw Samples (Locations) | AE1: # Flush Samples | AF1: # Total Samples | AG1: Laboratory | AH1: Results Received? | AI1: # FD Samples ≤1.4 µg/L Pb | AJ1: # Flush Samples ≤1.4 µg/L Pb | AK1: # FD Samples 1.5 - 15.4 µg/L | AL1: # Flush Samples 1.5 - 15.4 µg/L | AM1: # FD Samples ≥ 15.5 µg/L | AN1: # Flush Samples ≥ 15.5 µg/L | AO1: Total # samples analyzed | AP1: Results Sent Date | AQ1: Notes | AR1: MWRA? | AS1: DEP Region | AT1: PWS? | AU1: PWSID | AV1: PWS email | AW1: BOH email | AX1: School / EECF email | BC1: +AV:AV | BD1: EEC Provider Number
A2: 43979 | B2: 0-Out of Program | C2: 43896 | D2: W | E2: 2020-01-14T07:23:11-05:00 | F2: sch - 1579004422780 | G2: Cape Cod Lighthouse Charter School | H2: sch | I2: 195 Route 137 | K2: Harwich | L2: 02645 | M2: Paul | N2: Niles | O2: Executive Director | P2: 774-408-7994 | Q2: pniles@cclcs.info | R2: 195 Route 137 | T2: Harwich | U2: 02645 | V2: < 1988 | W2: 20+ | Z2: 4320530 | AR2: N | AS2: SERO | AT2: N | AU2: 4126000 | AW2: health@town.harwich.ma.us | BC2: =IF(ISBLANK(AC2),"",IF(AC2<TODAY(),K2,"")) | BD2: P-170209
A3: 43896 | B3: 0-Out of Program | C3: 43896 | D3: R | E3: 2020-01-17T17:03:06-05:00 | F3: ccf - 1579298404811 | G3: Paula's Family ChildCare | H3: FCC | I3: 23 Meadowcroft Street | K3: Lowell | L3: 01852 | M3: Paula | N3: Teixeira | O3: Educator | P3: 9789952068 | Q3: xrosa76@comcast.net | R3: 23 Meadowcroft St | T3: Lowell | U3: 01852 | V3: < 1988 | W3: 0-10 | X3: Teixeira, Paula Alexandra | Z3: 1579298404811 | AR3: N | AS3: NERO | AT3: N | AU3: 3160000 | AW3: jbelanger@lowellma.gov | BC3: =IF(ISBLANK(AC3),"",IF(AC3<TODAY(),K3,"")) | BD3: P-171241
A4: 44272 | B4: 0-Out of Program | C4: 43896 | D4: A | E4: 2020-02-05T07:07:10-05:00 | F4: ccf - 1580904391858 | G4: Children Of America | H4: LG | I4: 76 Vanderbilt Avenue | K4: Norwood | L4: 02062 | M4: Kerri | N4: Emidy | O4: Center Director | P4: 781-255-5778 | Q4: coanorwoodma@childrenofamerica.com | R4: 76 Vanderbilt Ave | T4: Norwood | U4: 02062 | V4: > 1988 | W4: 20+ | Y4: fea8-6cc9-a30d | Z4: 2912264 | AA4: Rick | AF4: =AD4+AE4 -> 0 | AO4: =AI4+AJ4+AK4+AL4+AM4+AN4 -> 0 | AQ4: Collected samples on their own. Out of program | AR4: N | AS4: SERO | AT4: N | AU4: 4220000 | AV4: mryan@norwoodma.gov | AX4: erin.craft@mass.gov | BC4: =IF(ISBLANK(AC4),"",IF(AC4<TODAY(),K4,""))
A5: 43979 | B5: 0-Out of Program | C5: 43896 | D5: R | E5: 2020-02-24T09:42:06-05:00 | F5: sch - 1582555056759 | G5: St. Mary's Parish School | H5: sch | I5: 35 Bartlett Street | K5: Westfield | L5: 01085 | M5: Patricia | N5: Howes | O5: School Nurse | P5: 413-568-2388x302 | Q5: phowes@stmsaints.org | R5: 35 Bartlett St. | T5: Westfield | U5: 01085 | V5: < 1988 | W5: 20+ | Z5: 3250810 | AR5: N | AS5: WERO | AW5: j.rouse@cityofwestfield.org | BC5: =IF(ISBLANK(AC5),"",IF(AC5<TODAY(),K5,"")) | BD5: P-171241
A6: 44083 | B6: 0-Out of Program | C6: 44046 | D6: A | E6: 2020-07-23T08:48:59-05:00 | F6: ccf - 1595512008876 | G6: Jane's Family ChildCare | H6: FCC | I6: 16 Noble Street | K6: Newton - West | L6: 02465 | M6: Jane | N6: Malieswski | O6: Owner/ Family Childcare | P6: 617-818-1331 | Q6: fourmals@comcast.net | R6: 16 Noble St. | T6: West Newton | U6: 02465 | V6: < 1988 | W6: 20+ | X6: Malieswski, Jane | Y6: 0f45-a307-2024 | Z6: 692835 | AA6: Gene | AQ6: Opted out, said tested water when bought house | AR6: N | AS6: NERO | AT6: Y | AU6: 3207000 | AW6: dyoungblood@newtonma.gov | BC6: =IF(ISBLANK(AC6),"",IF(AC6<TODAY(),K6,""))
A7: 44315 | B7: 0-Out of Program | C7: 44291 | D7: A | E7: 2021-03-30T20:44:57-05:00 | F7: sch - 1617154968564 | G7: Debbie's Daycare | H7: FCC | I7: 195 East Union Stret | K7: Ashland | L7: 01721 | M7: Debra | N7: Butler | O7: owner/Director | P7: 508-881-4283 | Q7: whtagal@aol.com | R7: 195 East Union St. | T7: Ashland | U7: 1721 | V7: < 1988 | W7: 0-10 | Z7: 702239 | AA7: Kate | AQ7: Closing facility.Not going to participate. | AR7: N/Y | AS7: NERO | AT7: N | AU7: 3014000 | AV7: dpw@ashlandmass.com | AW7: moram@ashlandmass.com | AX7: erin.craft@mass.gov | BC7: =IF(ISBLANK(AC7),"",IF(AC7<TODAY(),K7,"")) | BD7: P-169602
A8: 44349 | B8: 0-Out of Program | C8: 44308 | D8: A | E8: 2021-04-05 T12:25 PM | G8: Brackett, Renee | H8: FCC | I8: 512 Pleasant Street null | K8: Southbridge | L8: 01550 | M8: Renee | N8: Brackett | O8: Family child care provider | P8: 774-230-3771 | Q8: rbrackett50@msn.com | R8: 512 Pleasant Street null | T8: Southbridge | U8: 01550 | Y8: 946e-522c-49ea | Z8: T0000066 | AA8: Kate | AB8: J. Brecket | AC8: 44345 | AD8: 3 | AE8: 3 | AF8: 6 | AG8: Con-Test | AO8: =AI8+AJ8+AK8+AL8+AM8+AN8 -> 0 | AR8: N | AS8: CERO | AT8: N | AU8: 2278000 | AV8: sgregoire@southbridgemass.org | AW8: apelletier@town.auburn.ma.us | AX8: erin.craft@mass.gov
A9: 44299 | B9: 0-Out of Program | C9: 44298 | D9: A | E9: 2021-04-05T13:09:22-05:00 | F9: ccf - 8029157_P-183302 | G9: Wayland Montessori Preschool | H9: LG | I9: 5 Damon Street | K9: Wayland | L9: 01778 | M9: Tyla | N9: Corfield | O9: Assistant Director | P9: 508-655-5742 | Q9: tyla.waylandmontessori@gmail.com | R9: 5 Damon Street | T9: Wayland | U9: 1778 | V9: < 1988 | W9: 11-20 | Z9: 8029157 | AA9: Kate | AF9: =AD9+AE9 -> 0 | AO9: =AI9+#REF!+AK9+AL9+AM9+AN9 -> #REF! | AR9: N | AS9: NERO | AT9: ? | AU9: 3315000 | AV9: dmillette@wayland.ma.us | AW9: jjunghanns@wayland.ma.us | AX9: erin.craft@mass.gov
A10: 44299 | B10: 0-Out of Program | C10: 44298 | D10: A | E10: 2021-04-05T13:12:35-05:00 | F10: ccf - 200566_P-169520 | G10: Community Nursery School of Wayland | H10: LG | I10: 5 Damon Street | K10: Wayland | L10: 01778 | M10: Beth | N10: Fuce | O10: Director | P10: 508-651-2555 | Q10: elizabethfuce@gmail.com | R10: 5 Damon Street | T10: Wayland | U10: 1778 | V10: < 1988 | W10: 11-20 | Z10: 200566 | AA10: Kate | AF10: =AD10+AE10 -> 0 | AO10: =AI10+#REF!+AK10+AL10+AM10+AN10 -> #REF! | AR10: N | AS10: NERO | AT10: ? | AU10: 3315000 | AV10: dmillette@wayland.ma.us | AW10: jjunghanns@wayland.ma.us | AX10: erin.craft@mass.gov
A11: 44386 | B11: 0-Out of Program | C11: 43895 | E11: 2020-01-14T09:12:16-05:00 | F11: ccf - 2911795_P-177108 | G11: Crayon College, Inc. | H11: LG | I11: 24 Main Street | K11: Kingston | L11: 02364 | M11: Paula | N11: Ryan | O11: Director | P11: 781-585-5437 | Q11: directorkingston@crayoncollege.us | R11: 24 Main St | T11: Kingston | U11: 02364 | V11: < 1988 | W11: 20+ | Z11: 2911795 | AA11: Gene | AF11: =AD11+AE11 -> 0 | AO11: =AI11+AJ11+AK11+AL11+AM11+AN11 -> 0 | AQ11: e-mail requesting site plan, program attachments, follow up by phone wk 7/9/21 Not interested in the program already tested | AR11: N | AS11: SERO | AT11: N | AU11: 4145000 | AV11: mjdarsch@kingstonmass.org | AW11: mherzberg@kingstonmass.org | AX11: erin.craft@mass.gov
A12: 44410 | B12: 0-Out of Program | C12: 44298 | E12: 2021-04-08T06:48:56-05:00 | F12: ccf - 1617882459921 | G12: Nurtury | H12: LG | I12: 436 Tremont Street | K12: Boston | L12: 02116 | M12: George | N12: Pereira | O12: Director of Properties | P12: 617-828-9987 | Q12: gpereira@nurturyboston.org | R12: 436 Tremont Street | T12: Boston | U12: 2119 | V12: < 1988 | W12: 20+ | Y12: 62c9-56fd-6f45 | Z12: 200912 | AA12: Gene | AF12: =AD12+AE12 -> 0 | AO12: =AI12+AJ12+AK12+AL12+AM12+AN12 -> 0 | AQ12: Nurtury is leaving this location in August 2021 | AR12: Y | AS12: NERO | AT12: N | AU12: 3035000 | AV12: sullivanjp@bwsc.org | AW12: rnieves@bphc.org | AX12: erin.craft@mass.gov | BC12: =IF(ISBLANK(AC12),"",IF(AC12<TODAY(),K12,""))
A13: 44467 | B13: 0-Out of Program | E13: 44008 | F13: 2020-06-08T20:27:28-05:00 | G13: ccf - 1591665777391 | H13: Diane Gorman Daycare | I13: FCC | J13: 19 Fairview Avenue | L13: Lynn | M13: 01904 | N13: Diane | O13: Gorman | P13: Daycare provider | Q13: 617-285-7731 | R13: dgorman1262@gmail.com | S13: 19 Fairview Ave. | U13: Lynn | V13: 01904 | W13: < 1988 | X13: 0-10 | Z13: 39ea-a1a7-5c9c | AA13: 623848 | AB13: Gene | AE13: 2 | AF13: 2 | AG13: =AE13+AF13 -> 4 | AP13: =AJ13+AK13+AL13+AM13+AN13+AO13 -> 0 | AR13: Spoke 9/29 Opting Out | AS13: N | AT13: NERO | AU13: N | AV13: 3163000 | AW13: hsamuelson@lynnwatersewer.org | AX13: mdesmarais@lynnma.gov | AY13: erin.craft@mass.gov | BD13: =IF(ISBLANK(AD13),"",IF(AD13<TODAY(),L13,"")) | BE13: P-187858

Sheet Facilities
A1: Date Record Updated | B1: UMass Status | C1: Completion Level | D1: Completion Notes | E1: Date of DEP Decision | F1: Application Date & Time | G1: Code from Application Form | H1: Facility Name | I1: Facility Type | J1: Facility Street 1 | K1: Facility Street 2 | L1: ighton | M1: Facility Zip | N1: PPC First Name | O1: PPC Last Name | P1: PPC Job Title | Q1: PPC Phone | R1: PPC Email | S1: PPC Street 1 | T1: PPC Street 2 | U1: PPC Town | V1: PPC Zip | W1: Construction year | X1: Future Operations | Y1: Registered Name (EEC) if different than Col G | Z1: Report Tool Pin | AA1: Org Code | AB1: TAP Name | AC1: Sampler Name | AD1: Sampling Date | AE1: # First Draw Samples (Locations) | AF1: # Flush Samples | AG1: # Total Samples | AH1: Laboratory | AI1: Results Received? | AJ1: # FD Samples ≤1.4 µg/L Pb | AK1: # Flush Samples ≤1.4 µg/L Pb | AL1: # FD Samples 1.5 - 15.4 µg/L | AM1: # Flush Samples 1.5 - 15.4 µg/L | AN1: # FD Samples ≥ 15.5 µg/L | AO1: # Flush Samples ≥ 15.5 µg/L | AP1: Total # samples analyzed | AQ1: Results Sent Date | AR1: Notes | AS1: MWRA? | AT1: DEP Region | AU1: PWS? | AV1: PWSID | AW1: PWS email | AX1: BOH email | AY1: School / EECF email | BD1: +AV:AV | BE1: EEC Provider Number
A2: 44376 | B2: 9-Completed | C2: Remediation | D2: Routine flushing | E2: 44238 | F2: 2021-02-05T16:39:43-05:00 | G2: ccf - 1612561048565 | H2: The Cottage Garden EEC licensed Family Child Care | I2: FCC | J2: 135 Cottage Street | L2: Amherst | M2: 01002 | N2: Celia | O2: Riahi | P2: owner/teacher | Q2: 413-348-6035 | R2: celiariahi@gmail.com | S2: 135 Cottage St. | U2: Amherst | V2: 01002 | W2: < 1988 | X2: 0-10 | Z2: 533a 2250-cff7 | AA2: 7027845 | AB2: Kate | AC2: Celia Riahi | AD2: 44252 | AE2: =AJ2+AL2+AN2 -> 4 | AF2: =AK2+AM2+AO2 -> 4 | AG2: =AE2+AF2 -> 8 | AH2: Con-Test | AI2: 44264 | AJ2: 3 | AK2: 4 | AL2: 1 | AM2: 0 | AN2: 0 | AO2: 0 | AP2: =AJ2+AK2+AL2+AM2+AN2+AO2 -> 8 | AQ2: 44273 | AR2: SC- 2/25/21 @10:00AM | AS2: N | AT2: WERO | AU2: N | AV2: 1008000 | AW2: mooringg@amherstma.gov | AX2: dragone@amherstma.gov | AY2: erin.craft@mass.gov | BD2: =IF(ISBLANK(AD2),"",IF(AD2<TODAY(),L2,"")) -> Amherst | BE2: P-169908
A3: 44376 | B3: 9-Completed | C3: No Detect, Done | E3: 43895 | F3: 2020-02-05T12:06:07-05:00 | G3: ccf - 201243_P-169788 | H3: Cushman Scott Children's Center | I3: LG | J3: 71 Henry Street | L3: Amherst | M3: 01002 | N3: Mary Ann | O3: Ziomek | P3: Director | Q3: 413-549-1167 | R3: director@cushmanscott.org | S3: PO Box 9656 | T3: 71 Henry Street | U3: North Amherst | V3: 01059 | W3: < 1988 | X3: 20+ | Z3: d505-8872-779d | AA3: 201243 | AB3: Rick | AD3: 44082 | AE3: =AJ3+AL3+AN3 -> 1 | AF3: =AK3+AM3+AO3 -> 1 | AG3: =AE3+AF3 -> 2 | AH3: Con-Test | AI3: 44091 | AJ3: 1 | AK3: 1 | AL3: 0 | AM3: 0 | AN3: 0 | AO3: 0 | AP3: =AJ3+AK3+AL3+AM3+AN3+AO3 -> 2 | AQ3: 44137 | AR3: Notified by phone of ND; waiting on Boston letter for forwarding | AS3: N | AT3: WERO | AU3: N | AV3: 1008000 | AW3: mooringg@amherstma.gov | AX3: dragone@amherstma.gov | AY3: erin.craft@mass.gov | BD3: =IF(ISBLANK(AD3),"",IF(AD3<TODAY(),L3,"")) -> Amherst | BE3: P-169784
A4: 44377 | B4: 9-Completed | C4: No Detect, Done | E4: 43895 | F4: 2020-01-21T15:01:37-05:00 | G4: ccf - 1579636659305 | H4: Pre-K-Kidz Childcare and Preschool | I4: LG | J4: 464 Main Street | L4: Athol | M4: 01331 | N4: Rebecca | O4: Lanoue | P4: Owner | Q4: 978-830-4636 | R4: prekkidz01331@gmail.com | S4: 464 Main St. | U4: Athol | V4: 01331 | W4: undefined | X4: undefined | Y4: Lanoue, Rebecca | Z4: baee-7adf-559b | AA4: T0000040 | AB4: Rick | AD4: 44026 | AE4: =AJ4+AL4+AN4 -> 2 | AF4: =AK4+AM4+AO4 -> 2 | AG4: =AE4+AF4 -> 4 | AH4: Con-Test | AI4: 44042 | AJ4: 2 | AK4: 2 | AL4: 0 | AM4: 0 | AN4: 0 | AO4: 0 | AP4: =AJ4+AK4+AL4+AM4+AN4+AO4 -> 4 | AQ4: 11/11/2020 | AR4: Notified by phone of ND; waiting on Boston letter for forwarding | AS4: N | AT4: WERO | AU4: N | AV4: 1015000 | AW4: None | AX4: boh@townofathol.org | AY4: erin.craft@mass.gov | BD4: =IF(ISBLANK(AD4),"",IF(AD4<TODAY(),L4,"")) -> Athol
A5: 44377 | B5: 9-Completed | C5: Remediation | D5: Routine flushing | E5: 44298 | F5: 2021-04-10T06:37:17-05:00 | G5: ccf - 1618054528625 | H5: Robyn Roberts Family Day Care | I5: FCC | J5: 15 Oakwood Drive | L5: Belchertown | M5: 01007 | N5: Robyn | O5: Roberts | P5: Daycare Owner | Q5: 413-544-4057 | R5: belchertown4@yahoo.com | S5: 15 Oakwood Drive | U5: Belchertown | V5: 1007 | W5: > 1988 | X5: 20+ | Z5: 3c09-e910-9a96 | AA5: 606795 | AB5: Kate | AD5: 44348 | AE5: 2 | AF5: 2 | AG5: =AE5+AF5 -> 4 | AH5: Con-Test | AI5: 44358 | AJ5: 0 | AK5: 2 | AL5: 2 | AM5: 0 | AN5: 0 | AO5: 0 | AP5: =AJ5+AK5+AL5+AM5+AN5+AO5 -> 4 | AQ5: 44363 | AS5: N | AT5: WERO | AU5: ? | AV5: 1024000 | AW5: None | AX5: jmetcalf@townofware.com | AY5: erin.craft@mass.gov | BD5: =IF(ISBLANK(AD5),"",IF(AD5<TODAY(),L5,"")) -> Belchertown
A6: 44383 | B6: 9-Completed | C6: No Detect, Done | E6: 44295 | F6: 2021-04-02T11:34:48-05:00 | G6: ccf - 1617380723390 | H6: Acorn Patch Family Childcare | I6: FCC | J6: 6 Acorn Street | L6: Bellingham | M6: 02019 | N6: Kari | O6: Meszaros-Phaneuf | P6: Family Childcare Owner | Q6: 774-277-0591 | R6: kari.ann.meszaros@gmail.com | S6: 6 Acorn Street | U6: Bellingham | V6: 2019 | W6: > 1988 | X6: 0-10 | Z6: 0e20-9e79-f77f | AA6: T0000058 | AB6: Kate | AD6: 44326 | AE6: 3 | AF6: 3 | AG6: =AE6+AF6 -> 6 | AH6: RI Analytical | AI6: 44371 | AJ6: 3 | AK6: 3 | AL6: 0 | AM6: 0 | AN6: 0 | AO6: 0 | AP6: =AJ6+AK6+AL6+AM6+AN6+AO6 -> 6 | AQ6: 44372 | AR6: Lab Pick up scheduled 5/12/21. | AS6: N | AT6: CERO | AU6: N | AV6: 2025000 | AW6: None | AX6: bwilson@bellinghamma.org | AY6: erin.craft@mass.gov | BD6: =IF(ISBLANK(AD6),"",IF(AD6<TODAY(),L6,"")) -> Bellingham | BE6: P-177112
A7: 44377 | B7: 9-Completed | C7: No Detect, Done | E7: 43896 | F7: 2020-01-27T14:10:55-05:00 | G7: sch - 00350811 | H7: Shaloh House Day | I7: LG | J7: 29 Chestnut Hill Avenue | L7: Brighton | M7: 02135 | N7: Ilan | O7: Meyers | P7: Consultant | Q7: 617-787-2200 | R7: school@shaloh.org | S7: 29 Chestnut Hill Ave. | U7: Brighton | V7: 02135 | W7: < 1988 | X7: 20+ | Z7: b6eb-1eca-ea9c | AA7: 00350811 | AB7: Gene | AC7: Gene Brunelle | AD7: 44155 | AE7: =AJ7+AL7+AN7 -> 17 | AF7: =AK7+AM7+AO7 -> 17 | AG7: =AE7+AF7 -> 34 | AH7: RI Analytical | AI7: 44155 | AJ7: 17 | AK7: 17 | AL7: 0 | AM7: 0 | AN7: 0 | AO7: 0 | AP7: =AJ7+AK7+AL7+AM7+AN7+AO7 -> 34 | AQ7: 1/4/2021 | AR7: Samples collected 11/20, Delivered to RI Analytical 11/23 | AS7: Y | AT7: NERO | AU7: N | AV7: 3035000 | AW7: sullivanjp@bwsc.org | AX7: rnieves@bphc.org | AY7: erin.craft@mass.gov | BD7: =IF(ISBLANK(AD7),"",IF(AD7<TODAY(),L7,"")) -> Brighton | BE7: P-169530
A8: 44284 | B8: 9-Completed | C8: Follow-up | D8: Other | E8: 44225 | F8: 2021-01-22T14:57:21-05:00 | G8: ccf - 200321_P-169407 | H8: Canton Community Kindergarten | I8: LG | J8: 1541 Washington Street | L8: Canton | M8: 02021 | N8: Joe | O8: Kendall | P8: Resource Team Director | Q8: 312-206-2277 | R8: jpkendall13@aol.com | S8: 1541 Washington St. | U8: Canton | V8: 02021 | W8: < 1988 | X8: 20+ | Z8: a480-7d22-e39e | AA8: 200321 | AB8: Rick | AD8: 44251 | AE8: 2 | AF8: 2 | AG8: =AE8+AF8 -> 4 | AH8: Alpha Analytical | AI8: 44263 | AJ8: 1 | AK8: 2 | AL8: 1 | AM8: 0 | AN8: 0 | AO8: 0 | AP8: =AJ8+AK8+AL8+AM8+AN8+AO8 -> 4 | AQ8: 44284 | AR8: Flush the kitchen sink | AS8: Y | AT8: SERO | AU8: N | AV8: 4050000 | AW8: csykes@town.canton.ma.us | AX8: breardon@town.canton.ma.us | AY8: erin.craft@mass.gov | BD8: =IF(ISBLANK(AD8),"",IF(AD8<TODAY(),L8,"")) -> Canton | BE8: P-170547
A9: 44377 | B9: 9-Completed | C9: Follow-up | D9: Provide water bottles | E9: 43986 | F9: 2020-05-14T10:08:45-05:00 | G9: ccf - 8031747_P-185815 | H9: Youth Center, Inc. | I9: LG | J9: 191 Church Street | L9: Cheshire | M9: 01225 | N9: Sonia | O9: DiSanti | P9: Director | Q9: 413-652-5976 | R9: sonia@youthcenterinc.org | S9: 284 Franklin St. | U9: North Adams | V9: 01247 | W9: < 1988 | X9: 0-10 | Z9: 246d-95b5-6b90 | AA9: 8031747 | AB9: Kate | AD9: 44044 | AE9: =AJ9+AL9+AN9 -> 9 | AF9: =AK9+AM9+AO9 -> 9 | AG9: =AE9+AF9 -> 18 | AH9: Con-Test | AI9: 44063 | AJ9: 0 | AK9: 1 | AL9: 6 | AM9: 6 | AN9: 3 | AO9: 2 | AP9: =AJ9+AK9+AL9+AM9+AN9+AO9 -> 18 | AQ9: 44146 | AR9: Sampling complete; waiting on Boston letter for forwarding | AS9: N | AT9: WERO | AU9: N | AV9: 1058000 | AW9: Water2cheshire@gmail.com | AX9: mmoore@northadams-ma.gov | AY9: erin.craft@mass.gov | BD9: =IF(ISBLANK(AD9),"",IF(AD9<TODAY(),L9,"")) -> Cheshire | BE9: P-170913
A10: 44397 | B10: 9-Completed | C10: No Detect, Done | E10: 44358 | F10: 2021-05-26T12:02:23-05:00 | G10: ccf - 1622048480928 | H10: SolBe Learning | I10: LG | J10: 631 VFW Parkway | L10: Chestnut Hill | M10: 02467 | N10: Patricia | O10: Pirone | P10: Director | Q10: 617-784-9921 | R10: patty@solbelearning.com | S10: 643 VFW Parkway, Suite A | T10: Suite A | U10: Chestnut Hill | V10: 02467 | W10: > 1988 | X10: 0-10 | Z10: 1751-d745-e38e | AA10: T0000070 | AB10: Bob | AC10: Bob Hoyt | AD10: 44373 | AE10: 17 | AF10: 17 | AG10: =AE10+AF10 -> 34 | AH10: RI Analytical | AI10: 44386 | AJ10: 17 | AK10: 17 | AL10: 0 | AM10: 0 | AN10: 0 | AO10: 0 | AP10: =AJ10+AK10+AL10+AM10+AN10+AO10 -> 34 | AQ10: 44397 | AS10: N | AT10: NERO | AU10: N | AV10: 3035000 | AW10: sullivanjp@bwsc.org | AX10: rnieves@bphc.org | AY10: erin.craft@mass.gov | BD10: =IF(ISBLANK(AD10),"",IF(AD10<TODAY(),L10,"")) -> Chestnut Hill | BE10: P-169921
A11: 44383 | B11: 9-Completed | C11: No Detect, Done | E11: 43894 | F11: 2020-01-30T11:33:40-05:00 | G11: ccf - 201563_P-169959 | H11: Chicopee Child Development Center, Inc. | I11: LG | J11: 989 James Street | L11: Chicopee | M11: 01022 | N11: Joan | O11: Beaudry | P11: Business Administration | Q11: 413-593-3942 | R11: ccdckids69@gmail.com | S11: 989 James St. | U11: Chicopee | V11: 01022 | W11: < 1988 | X11: 20+ | Z11: ebcc-548d-4ead | AA11: 201563 | AB11: Kate | AC11: Joan Beaudry | AD11: 44166 | AE11: =AJ11+AL11+AN11 -> 1 | AF11: =AK11+AM11+AO11 -> 1 | AG11: =AE11+AF11 -> 2 | AH11: Con-Test | AI11: 44180 | AJ11: 1 | AK11: 1 | AL11: 0 | AM11: 0 | AN11: 0 | AO11: 0 | AP11: =AJ11+AK11+AL11+AM11+AN11+AO11 -> 2 | AQ11: 12/21/2020 | AS11: Y | AT11: WERO | AU11: N | AV11: 1061000 | AW11: None | AX11: lsanders@chicopeema.gov | AY11: erin.craft@mass.gov | BD11: =IF(ISBLANK(AD11),"",IF(AD11<TODAY(),L11,"")) -> Chicopee
A12: 44377 | B12: 9-Completed | C12: Follow-up | D12: Issue do not drink order | E12: 43895 | F12: 2020-01-30T07:53:47-05:00 | G12: ccf - 290324_P-170630 | H12: V. O. C. Child Care on Montgomery Street | I12: LG | J12: 374 Montgomery Street | L12: Chicopee | M12: 01020 | N12: Melinda | O12: Gnoza | P12: Center Director | Q12: 413-331-1331 | R12: Mgnoza@valleyopp.com | S12: 374 Montgomery St. | U12: Chicopee | V12: 01020 | W12: > 1988 | X12: 0-10 | Z12: 01ae-1b63-1c9a | AA12: 290324 | AB12: Kate | AD12: 44043 | AE12: =AJ12+AL12+AN12 -> 13 | AF12: =AK12+AM12+AO12 -> 13 | AG12: =AE12+AF12 -> 26 | AH12: Con-Test | AI12: 44054 | AJ12: 13 | AK12: 13 | AL12: 0 | AM12: 0 | AN12: 0 | AO12: 0 | AP12: =AJ12+AK12+AL12+AM12+AN12+AO12 -> 26 | AQ12: 11/3/2020 | AR12: Results back today 13 samples all ND. Lab has problem w/EEC #. | AS12: Y | AT12: WERO | AU12: N | AV12: 1061000 | AW12: None | AX12: lsanders@chicopeema.gov | AY12: erin.craft@mass.gov | BD12: =IF(ISBLANK(AD12),"",IF(AD12<TODAY(),L12,"")) -> Chicopee | BE12: P-170248
A13: 44383 | B13: 9-Completed | C13: No Detect, Done | E13: 43894 | F13: 2020-02-04T14:43:52-05:00 | G13: ccf - 300304_P-171076 | H13: Casper | I13: LG | J13: 580 Meadow Street | L13: Chicopee | M13: 01013 | N13: Jason | O13: Reed | P13: Executive Director | Q13: 413-206-4109 | R13: jasonr@bgcchicopee.org | S13: 580 Meadow St. | U13: Chicopee | V13: 01013 | W13: < 1988 | X13: 20+ | Z13: 6b8c-9a3f-9d61 | AA13: 300304 | AB13: Kate | AD13: 44082 | AE13: =AJ13+AL13+AN13 -> 3 | AF13: =AK13+AM13+AO13 -> 3 | AG13: =AE13+AF13 -> 6 | AH13: Con-Test | AI13: 44091 | AJ13: 3 | AK13: 3 | AL13: 0 | AM13: 0 | AN13: 0 | AO13: 0 | AP13: =AJ13+AK13+AL13+AM13+AN13+AO13 -> 6 | AQ13: 11/11/2020 | AS13: Y | AT13: WERO | AU13: N | AV13: 1061000 | AW13: None | AX13: lsanders@chicopeema.gov | AY13: erin.craft@mass.gov | BD13: =IF(ISBLANK(AD13),"",IF(AD13<TODAY(),L13,"")) -> Chicopee
A14: 44312 | B14: 9-Completed | C14: No Detect, Done | E14: 44046 | F14: 2020-03-06T10:23:35-05:00 | G14: ccf - 201852_P-170023 | H14: VOC Early Education and Care at Mt. Carmel | I14: LG | J14: 35 Mt Carmel Avenue | L14: Chicopee | M14: 01013 | N14: Jyton | O14: Hunter | P14: Director | Q14: 413-433-7363 | R14: jhunter@valleyopp.com | S14: 35 Mt.Carmel Ave. | U14: Chicopee | V14: 01013 | W14: < 1988 | X14: 20+ | Z14: c0b3-717b-9c62 | AA14: 201852 | AB14: Kate | AC14: Jyton Hunter | AD14: 44244 | AE14: 15 | AF14: 15 | AG14: =AE14+AF14 -> 30 | AH14: Con-Test | AI14: 44267 | AJ14: 15 | AK14: 15 | AL14: 0 | AM14: 0 | AN14: 0 | AO14: 0 | AP14: =AJ14+AK14+AL14+AM14+AN14+AO14 -> 30 | AQ14: 44312 | AR14: Sampling took place 2/17/21 and 3/12/21 because all sites were not done the first time | AS14: Y | AT14: WERO | AU14: N | AV14: 1061000 | AW14: None | AX14: lsanders@chicopeema.gov | AY14: erin.craft@mass.gov | BD14: =IF(ISBLANK(AD14),"",IF(AD14<TODAY(),L14,"")) -> Chicopee | BE14: P-170081
A15: 44012 | B15: 9-Completed | C15: No Detect, Done | E15: 44008 | F15: 2020-06-08T12:04:42-05:00 | G15: ccf - 1591635774998 | H15: Skylight daycare | I15: FCC | J15: 101 Angela Drive | L15: Chicopee | M15: 01020 | N15: Olivia | O15: Poellnitz | P15: daycare provider | Q15: 413-386-0040 | R15: oliviapoe370@gmail.com | S15: 101 Angela Drive | U15: Chicopee | V15: 01020 | W15: > 1988 | X15: 0-10 | Y15: Poellnitz, Olivia | Z15: 6fbf-a9dd-f4d7 | AA15: T0000044 | AB15: Kate | AC15: Olivia Poellnitz | AD15: 44148 | AE15: =AJ15+AL15+AN15 -> 2 | AF15: =AK15+AM15+AO15 -> 2 | AG15: =AE15+AF15 -> 4 | AH15: Con-Test | AI15: 44153 | AJ15: 2 | AK15: 2 | AL15: 0 | AM15: 0 | AN15: 0 | AO15: 0 | AP15: =AJ15+AK15+AL15+AM15+AN15+AO15 -> 4 | AQ15: 44159 | AR15: Sample Collection Scheduled 11/20 | AS15: Y | AT15: WERO | AU15: N | AV15: 1061000 | AW15: None | AX15: lsanders@chicopeema.gov | AY15: erin.craft@mass.gov | BD15: =IF(ISBLANK(AD15),"",IF(AD15<TODAY(),L15,"")) -> Chicopee | BE15: P-244643
A16: 44467 | B16: 9-Completed | C16: No Detect, Done | E16: 44183 | F16: 2020-12-11T18:54:03-05:00 | G16: ccf - 1607730636142 | H16: Nurture Nest Daycare | I16: FCC | J16: 224 Blanchard Street | L16: Chicopee | M16: 01020 | N16: Jennifer | O16: Wall | P16: Owner of licensed home daycare | Q16: 413-250-1980 | R16: Jennwall1181@gmail.com | S16: 224 Blanchard St. | T16: 224 Blanchard St. | U16: Chicopee | V16: 01020 | W16: > 1988 | X16: 11-20 | Y16: Wall, Jennifer | Z16: 1278-9cc8-3b08 | AA16: 8030099 | AB16: Kate | AC16: Jenn Wall | AD16: 44398 | AE16: 3 | AF16: 3 | AG16: =AE16+AF16 -> 6 | AH16: Con-Test | AI16: 44461 | AJ16: 3 | AK16: 3 | AL16: 0 | AM16: 0 | AN16: 0 | AO16: 0 | AP16: =AJ16+AK16+AL16+AM16+AN16+AO16 -> 6 | AQ16: 44466 | AR16: Texted her for a sample collection date... | AS16: Y | AT16: WERO | AU16: N | AV16: 1061000 | AW16: None | AX16: lsanders@chicopeema.gov | AY16: erin.craft@mass.gov | BD16: =IF(ISBLANK(AD16),"",IF(AD16<TODAY(),L16,"")) -> Chicopee | BE16: P-182770
A17: 44146 | B17: 9-Completed | C17: No Detect, Done | E17: 44008 | F17: 2020-06-08T11:14:28-05:00 | G17: ccf - 1591632708973 | H17: Little squirts family daycare | I17: FCC | J17: 183 S. Shirkshire Road | L17: Conway | M17: 01341 | N17: Jennifer | O17: Romanovicz | P17: Owner / operator home daycare | Q17: 413-635-8357 | R17: T.hunter3737@gmail.com | S17: 183 S. Shirkshire Rd | U17: Conway | V17: 01341 | W17: > 1988 | X17: 11-20 | Y17: Romanovicz, Jennifer R | Z17: 9e29-36c3-7e18 | AA17: 697776 | AB17: Rick | AC17: Jenn Romanocicz | AD17: 44055 | AE17: =AJ17+AL17+AN17 -> 2 | AF17: =AK17+AM17+AO17 -> 2 | AG17: =AE17+AF17 -> 4 | AH17: Con-Test | AI17: 44067 | AJ17: 2 | AK17: 2 | AL17: 0 | AM17: 0 | AN17: 0 | AO17: 0 | AP17: =AJ17+AK17+AL17+AM17+AN17+AO17 -> 4 | AQ17: 44146 | AS17: N | AT17: WERO | AU17: ? | AV17: 1068006 | AW17: None | AX17: boardofhealth@townofconway.com | AY17: erin.craft@mass.gov | BD17: =IF(ISBLANK(AD17),"",IF(AD17<TODAY(),L17,"")) -> Conway | BE17: P-170164
A18: 44211 | B18: 9-Completed | C18: Follow-up | D18: Put fountains out of commission | E18: 43895 | F18: 2020-01-16T11:34:23-05:00 | G18: ccf - 2912100_P-177316 | H18: Our Lady's Child Care Center | I18: LG | J18: 35 Pleasant Street | L18: Easthampton | M18: 01027 | N18: Jon | O18: Melanson | P18: Assistant Director | Q18: 413-527-6133 | R18: office2olccc@gmail.com | S18: 35 Pleasant Street | U18: Easthampton | V18: 01027 | W18: < 1988 | X18: 20+ | Z18: 0fff-1177-0878 | AA18: 2912100 | AB18: Kate | AC18: Perri Taylor | AD18: 44180 | AE18: =AJ18+AL18+AN18 -> 1 | AF18: =AK18+AM18+AO18 -> 0 | AG18: =AE18+AF18 -> 1 | AH18: Con-Test | AI18: 44201 | AJ18: 1 | AK18: 0 | AL18: 0 | AM18: 0 | AN18: 0 | AO18: 0 | AP18: =AJ18+AK18+AL18+AM18+AN18+AO18 -> 1 | AQ18: 1/15/2021 | AR18: Received labels, resent bottle order with Con-Test | AS18: N | AT18: WERO | AU18: N | AV18: 1087000 | AW18: mczerwiec@easthamptonma.gov | AX18: beichstaedt@easthamptonma.gov | AY18: erin.craft@mass.gov | BD18: =IF(ISBLANK(AD18),"",IF(AD18<TODAY(),L18,"")) -> Easthampton
A19: 44379 | B19: 9-Completed | C19: Remediation | D19: Routine flushing | E19: 44292 | F19: 2021-03-31T11:33:28-05:00 | G19: ccf - 201962_P-170039 | H19: Guild of St. Agnes - Fitchburg | I19: FCC | J19: 9 Payson Street | L19: Fitchburg | M19: 01420 | N19: Marileia | O19: Abade | P19: Educator/Provider | Q19: 857-236-9920 | R19: sunflowerfdc@gmail.com | S19: 9 Payson St. | U19: Fitchburg | V19: 1420 | W19: < 1988 | X19: 0-10 | Y19: St. Agnes-Fitchburg | Z19: 89f9-3c87-50e8 | AA19: 201962 | AB19: Kate | AC19: Marileia Abade | AD19: 44327 | AE19: 3 | AF19: 2 | AG19: =AE19+AF19 -> 5 | AH19: Con-Test | AI19: 44351 | AJ19: 1 | AK19: 2 | AL19: 2 | AM19: 0 | AN19: 0 | AO19: 0 | AP19: =AJ19+AK19+AL19+AM19+AN19+AO19 -> 5 | AQ19: 44354 | AS19: N | AT19: CERO | AU19: N | AV19: 2097000 | AW19: ekirrane@FITCHBURGMA.GOV | AX19: scurry@fitchburgma.gov | AY19: erin.craft@mass.gov | BD19: =IF(ISBLANK(AD19),"",IF(AD19<TODAY(),L19,"")) -> Fitchburg | BE19: P-182554
A20: 44448 | B20: 9-Completed | C20: No Detect, Done | E20: 44393 | F20: 2021-07-14T20:27:44-05:00 | G20: ccf - 1626312258228 | H20: Guertin Day Care | I20: FCC | J20: 495 Burts Pit Road | L20: Florence | M20: 1062 | N20: Shirley | O20: Guertin | P20: Educator/provider/owner | Q20: 413-588-4674 | R20: Shirleyguertin@comcast.net | S20: 495 Burtspit Rd | U20: Florence | V20: 1062 | W20: > 1988 | X20: 11-20 | Z20: 143e-1900-7e05 | AA20: 699137 | AB20: Kate | AC20: Shirley Guertin | AD20: 44433 | AE20: 3 | AF20: 3 | AG20: =AE20+AF20 -> 6 | AH20: Con-Test | AI20: 44446 | AJ20: 3 | AK20: 3 | AL20: 0 | AM20: 0 | AN20: 0 | AO20: 0 | AP20: =AJ20+AK20+AL20+AM20+AN20+AO20 -> 6 | AQ20: 44448 | AR20: Can sample anytime. | AS20: N | AT20: WERO | AU20: N | AV20: 1214000 | AW20: none | AX20: moleary@northamptonma.gov | AY20: erin.craft@mass.gov | BD20: =IF(ISBLANK(AD20),"",IF(AD20<TODAY(),L20,"")) -> Florence
A21: 44397 | B21: 9-Completed | C21: Follow-up | D21: Issue do not drink order | E21: 44298 | F21: 2021-04-09T10:49:55-05:00 | G21: ccf - 201270_P-169798 | H21: Giving Tree School | I21: LG | J21: 3 Wood Avenue | L21: Gill | M21: 01354 | N21: Haley | O21: Anderson | P21: Program Administrator | Q21: 413-863-9218 | R21: admin@givingtreeschool.org | S21: 3 Wood Avenue | U21: Gill | V21: 1354 | W21: < 1988 | X21: 20+ | Z21: 19d5-5d2c-3224 | AA21: 201270 | AB21: Kate | AC21: Haley Anderson | AD21: 44331 | AE21: 5 | AF21: 5 | AG21: =AE21+AF21 -> 10 | AH21: Con-Test | AI21: 44342 | AJ21: 0 | AK21: 5 | AL21: 4 | AM21: 0 | AN21: 1 | AO21: 0 | AP21: =AJ21+AK21+AL21+AM21+AN21+AO21 -> 10 | AQ21: 44343 | AS21: N | AT21: WERO | AU21: N | AV21: 1106000 | AW21: jeff.suprenant@comcast.net | AX21: lwhite@frcog.org | AY21: erin.craft@mass.gov | BD21: =IF(ISBLANK(AD21),"",IF(AD21<TODAY(),L21,"")) -> Gill | BE21: P-170912
A22: 44343 | B22: 9-Completed | C22: Follow-up | D22: Provide bottled water | E22: 44281 | F22: 2020-05-14T12:02:15-05:00 | G22: ccf - 8029384 | H22: Alphabet Soup Preschool Plus of Granby | I22: LG | J22: 55 Taylor Street | L22: Granby | M22: 01033 | N22: Bobbi | O22: Rougeau | P22: Owner | Q22: 413-335-7635 | R22: missbobbi.rougeau@gmail.com | S22: 166 West State St. | U22: Granby | V22: 01033 | W22: < 1988 | X22: 11-20 | Z22: c136-93b4-a6b5 | AA22: 8029384 | AB22: Kate | AC22: Bobbi Rougeau | AD22: 44327 | AE22: 1 | AF22: 1 | AG22: =AE22+AF22 -> 2 | AH22: Con-Test | AI22: 44335 | AJ22: 0 | AK22: 1 | AL22: 1 | AM22: 0 | AN22: 0 | AO22: 0 | AP22: =AJ22+AK22+AL22+AM22+AN22+AO22 -> 2 | AQ22: 44343 | AS22: N | AT22: WERO | AU22: Y | AV22: 1111037 | AW22: bobbischildcare@comcast.net | AX22: boh@granbyma.org | AY22: erin.craft@mass.gov | BD22: =IF(ISBLANK(AD22),"",IF(AD22<TODAY(),L22,"")) -> Granby | BE22: P-169909
A23: 44377 | B23: 9-Completed | C23: No Detect, Done | E23: 44166 | F23: 2020-11-25T10:17:30-05:00 | G23: sch - 04970205 | H23: Pioneer Valley Chinese Immersion Charter School | I23: sch | J23: 317 Russell Street | L23: Hadley | M23: 01035 | N23: Kevin | O23: Lawson | P23: Director of Operations | Q23: 413-582-7040 | R23: klawson@pvcics.org | S23: 317 Russell St. | U23: Hadley | V23: 01035 | W23: < 1988 | X23: 20+ | Z23: c324-88cf-2475 | AA23: 04970205 | AB23: Kate | AC23: Kevin Lawson | AD23: 44224 | AE23: 9 | AF23: 9 | AG23: =AE23+AF23 -> 18 | AH23: Con-Test | AI23: 44236 | AJ23: 9 | AK23: 9 | AL23: 0 | AM23: 0 | AN23: 0 | AO23: 0 | AP23: =AJ23+AK23+AL23+AM23+AN23+AO23 -> 18 | AQ23: 44246 | AR23: Received amended Sample Plan1/23, into Tool, created COC, Sampling 1/28 | AS23: N | AT23: WERO | AU23: N | AV23: 1117002 | AW23: publicworks@hadleyma.org | AX23: health@hadleyma.org | AY23: ruth.e.hersh@mass.gov | BD23: =IF(ISBLANK(AD23),"",IF(AD23<TODAY(),L23,"")) -> Hadley | BE23: P-170209
A24: 44377 | B24: 9-Completed | C24: Remediation | D24: Put fountains out of commission | E24: 43895 | F24: 2020-01-24T12:16:31-05:00 | G24: ccf - 8032025_P-186284 | H24: Valley Opportunity Council at Sullivan | I24: LG | J24: 400 Jarvis Avenue | L24: Holyoke | M24: 01040 | N24: Cassandra | O24: Roche | P24: Center Director | Q24: 413-265-8869 | R24: croche@valleyopp.com | S24: 400 Jarvis Ave. | U24: Holyoke | V24: 01040 | W24: < 1988 | X24: 0-10 | Z24: 973e-2f63-20fc | AA24: 8032025 | AB24: Kate | AC24: Cassandra Roche | AD24: 44243 | AE24: 1 | AF24: 1 | AG24: =AE24+AF24 -> 2 | AH24: Con-Test | AI24: 44250 | AJ24: 0 | AK24: 1 | AL24: 1 | AM24: 0 | AN24: 0 | AO24: 0 | AP24: =AJ24+AK24+AL24+AM24+AN24+AO24 -> 2 | AQ24: 2/25/2021 | AR24: Using delivered water cooler; ceased using faucet. | AS24: N | AT24: WERO | AU24: N | AV24: 1137000 | AW24: contid@holyoke.org | AX24: gonsalvess@holyoke.org | AY24: erin.craft@mass.gov
A25: 44377 | B25: 9-Completed | C25: Remediation | D25: Issue do not drink order | E25: 43894 | F25: 2020-01-23T08:11:04-05:00 | G25: ccf - 2911908_P-177208 | H25: Valley Opportunity Council @Churchill Homes | I25: LG | J25: 334 Elm Street | L25: Holyoke | M25: 01040 | N25: Allyson | O25: Lopez | P25: Center director of Early Educaion And Care Center | Q25: 413-534-2480 | R25: ALopez@valleyopp.com | S25: 334 Elm St. | U25: Holyoke | V25: 01040 | W25: > 1988 | X25: 11-20 | Z25: b765-6cef-2c82 | AA25: 2911908 | AB25: Kate | AD25: 44113 | AE25: =AJ25+AL25+AN25 -> 14 | AF25: =AK25+AM25+AO25 -> 14 | AG25: =AE25+AF25 -> 28 | AH25: Con-Test | AI25: 44131 | AJ25: 0 | AK25: 14 | AL25: 14 | AM25: 0 | AN25: 0 | AO25: 0 | AP25: =AJ25+AK25+AL25+AM25+AN25+AO25 -> 28 | AQ25: 11/11/2020 | AR25: Called and left message 10/5 | AS25: N | AT25: WERO | AU25: N | AV25: 1137000 | AW25: contid@holyoke.org | AX25: gonsalvess@holyoke.org | AY25: erin.craft@mass.gov
A26: 44377 | B26: 9-Completed | C26: No response | D26: Other | E26: 43895 | F26: 2020-01-30T09:51:12-05:00 | G26: ccf - 1580395555466 | H26: Valley Opportunity Council At Beaudoin Village | I26: LG | J26: 16 Barrett Avenue | L26: Holyoke | M26: 01040 | N26: Melody | O26: Robbins | P26: Center Director | Q26: 413-420-0107 | R26: mrobbins@valleyopp.com | S26: 16 Barrett Ave. | U26: Holyoke | V26: 01040 | W26: > 1988 | X26: 0-10 | Z26: 8948-a653-4791 | AA26: 2911803 | AB26: Kate | AD26: 44085 | AE26: =AJ26+AL26+AN26 -> 7 | AF26: =AK26+AM26+AO26 -> 7 | AG26: =AE26+AF26 -> 14 | AH26: Con-Test | AI26: 44131 | AJ26: 0 | AK26: 6 | AL26: 6 | AM26: 1 | AN26: 1 | AO26: 0 | AP26: =AJ26+AK26+AL26+AM26+AN26+AO26 -> 14 | AQ26: 11/11/2020 | AR26: Facility Closed 9/12/20 | AS26: N | AT26: WERO | AU26: N | AV26: 1137000 | AW26: contid@holyoke.org | AX26: gonsalvess@holyoke.org | AY26: erin.craft@mass.gov | BD26: =IF(ISBLANK(AD26),"",IF(AD26<TODAY(),L26,"")) -> Holyoke | BE26: P-170629
A27: 44446 | B27: 9-Completed | C27: Follow-up | D27: Put fountains out of commission | E27: 43895 | F27: 2020-02-10T12:42:09-05:00 | G27: sch - 04531001 | H27: Holyoke Community Charter School | I27: sch | J27: 2200 Northampton Street | L27: Holyoke | M27: 01040 | N27: Thomas | O27: Paquin | P27: Facilities Director | Q27: 413-563-0002 | R27: tpaquin@sabis.net | S27: 2200 Northampton St. | U27: Holyoke | V27: 01040 | W27: > 1988 | X27: 20+ | Z27: 19ff-7090-f9f8 | AA27: 04531001 | AB27: Kate | AC27: Tom Paquin | AD27: 44203 | AE27: 15 | AF27: 15 | AG27: =AE27+AF27 -> 30 | AH27: Con-Test | AI27: 44222 | AJ27: 6 | AK27: 7 | AL27: 5 | AM27: 6 | AN27: 4 | AO27: 2 | AP27: =AJ27+AK27+AL27+AM27+AN27+AO27 -> 30 | AQ27: 1/28/2021 | AR27: Results in, action items done in the Tool. | AS27: N | AT27: WERO | AU27: N | AV27: 1137000 | AW27: contid@holyoke.org | AX27: gonsalvess@holyoke.org | AY27: ruth.e.hersh@mass.gov
A28: 44377 | B28: 9-Completed | C28: Follow-up | D28: Provide bottled water | E28: 43894 | F28: 2020-02-12T11:29:43-05:00 | G28: ccf - 8032026_P-186285 | H28: Valley Opportunity Council at Morgan | I28: LG | J28: 596 South Bridge Street | L28: Holyoke | M28: 01040 | N28: Jessica | O28: O'Connor | P28: Center Director | Q28: 413-537-0529 | R28: JOConnor@valleyopp.com | S28: 596 South Bridge St. | U28: Holyoke | V28: 01022 | W28: < 1988 | X28: 0-10 | Z28: 6ca7-0a00-89b6 | AA28: 8032026 | AB28: Kate | AC28: JOConnor | AD28: 44343 | AE28: 2 | AF28: 2 | AG28: =AE28+AF28 -> 4 | AH28: Con-Test | AI28: 44370 | AJ28: 0 | AK28: 1 | AL28: 1 | AM28: 1 | AN28: 1 | AO28: 0 | AP28: =AJ28+AK28+AL28+AM28+AN28+AO28 -> 4 | AQ28: 44371 | AR28: Called and LM 3/3/21 | AS28: N | AT28: WERO | AU28: N | AV28: 1137000 | AW28: contid@holyoke.org | AX28: gonsalvess@holyoke.org | AY28: erin.craft@mass.gov | BD28: =IF(ISBLANK(AD28),"",IF(AD28<TODAY(),L28,"")) -> Holyoke | BE28: P-211694
A29: 44254 | B29: 9-Completed | C29: Replacement | D29: Provide bottled water | E29: 44201 | F29: 2020-12-28T14:13:21-05:00 | G29: ccf - 201300_P-169805 | H29: Lenox Children's Center | I29: LG | J29: 9 Old Center Street | L29: Lenox | M29: 01240 | N29: Bob | O29: Horn | P29: Water Superintendent | Q29: 413-637-5521 | R29: bhorn@townoflenox.com | S29: Town of Lenox | T29: 275 Main Street | U29: Lenox | V29: 01240 | W29: < 1988 | X29: 20+ | Z29: 18ee-4225-1fe9 | AA29: 201300 | AB29: Rick | AD29: 44245 | AE29: 3 | AF29: 3 | AG29: =AE29+AF29 -> 6 | AH29: Con-Test | AI29: 44252 | AJ29: 0 | AK29: 1 | AL29: 2 | AM29: 2 | AN29: 1 | AO29: 0 | AP29: =AJ29+AK29+AL29+AM29+AN29+AO29 -> 6 | AQ29: 44254 | AR29: Bob Horn will send samples back Thursday 2/18 | AS29: N | AT29: WERO | AU29: N | AV29: 1152000 | AW29: bhorn@townoflenox.com | AX29: jim@tritownhealth.org | AY29: erin.craft@mass.gov | BD29: =IF(ISBLANK(AD29),"",IF(AD29<TODAY(),L29,"")) -> Lenox | BE29: P-185897
A30: 44377 | B30: 9-Completed | C30: Follow-up | D30: Issue do not drink order | E30: 44292 | F30: 2021-04-01T17:11:06-05:00 | G30: ccf - 1617314940090 | H30: Kristen’s home daycare | I30: FCC | J30: 200 Whitcomb Avenue | L30: Littleton | M30: 01460 | N30: Kristen | O30: Ferrante | P30: Home daycare provider | Q30: 978-394-2648 | R30: Dak30@comcast.net | S30: 200 Whitcomb Ave | U30: Littleton | V30: 01460 | W30: > 1988 | X30: 11-20 | Z30: 8e68-1f21-a035 | AA30: 626347 | AB30: Kate | AC30: Kristen Ferante | AD30: 44309 | AE30: 3 | AF30: 3 | AG30: =AE30+AF30 -> 6 | AH30: RI Analytical | AI30: yes | AJ30: 1 | AK30: 3 | AL30: 1 | AM30: 0 | AN30: 1 | AO30: 0 | AP30: =AJ30+AK30+AL30+AM30+AN30+AO30 -> 6 | AQ30: 44330 | AS30: N | AT30: CERO | AU30: N | AV30: 2158000 | AW30: cgodfrey@lelwd.com | AX30: jgarreffi@nashoba.org | AY30: erin.craft@mass.gov | BD30: =IF(ISBLANK(AD30),"",IF(AD30<TODAY(),L30,"")) -> Littleton | BE30: P-169503
A31: 44475 | B31: 9-Completed | C31: Follow-up | D31: Routine flushing | E31: 44293 | F31: 2021-04-03T10:03:58-05:00 | G31: ccf - 1617462173740 | H31: Stephani's Childcare | I31: FCC | J31: 36 Fairlawn Street | L31: Lowell | M31: 01851 | N31: Valessa | O31: Marques | P31: Provider | Q31: 978-967-9909 | R31: valessamarques@hotmail.com | S31: 36 Fairlawn St. | U31: Lowell | V31: 1851 | W31: > 1988 | X31: 11-21 | Y31: Valessa Marquez | Z31: fa5d-72ce-d0d8 | AA31: 8028369 | AB31: Kate | AC31: Valessa | AD31: 44433 | AE31: 5 | AF31: 5 | AG31: =AE31+AF31 -> 10 | AH31: Con-Test | AI31: 44463 | AJ31: 3 | AK31: 5 | AL31: 2 | AM31: 0 | AN31: 0 | AO31: 0 | AP31: =AJ31+AK31+AL31+AM31+AN31+AO31 -> 10 | AQ31: 44475 | AR31: Collected and were picked up by Con-Test labs not RI Analytical... | AS31: N | AT31: NERO | AU31: N | AV31: 3160000 | AW31: None | AX31: jbelanger@lowellma.gov | AY31: erin.craft@mass.gov | BD31: =IF(ISBLANK(AD31),"",IF(AD31<TODAY(),L31,"")) -> Lowell | BE31: P-183302
A32: 44399 | B32: 9-Completed | C32: No Detect, Done | E32: 43895 | F32: 2020-02-17T07:45:24-05:00 | G32: ccf - 291019_P-170913 | H32: Ludlow Boys & Girls Club Child Care | I32: LG | J32: 91 Claudias Way | L32: Ludlow | M32: 01056 | N32: Sarah | O32: Goodwin | P32: Director of Operational Services | Q32: 413-583-2072 | R32: sgoodwin@ludlowbgc.org | S32: 91 Claudia's Way | U32: Ludlow | V32: 01056 | W32: undefined | X32: undefined | Z32: 4c3b-bf47-4e83 | AA32: 291019 | AB32: Kate | AC32: Sarah Goodwin | AD32: 44133 | AE32: =AJ32+AL32+AN32 -> 6 | AF32: =AK32+AM32+AO32 -> 6 | AG32: =AE32+AF32 -> 12 | AH32: Con-Test | AI32: 44144 | AJ32: 6 | AK32: 6 | AL32: 0 | AM32: 0 | AN32: 0 | AO32: 0 | AP32: =AJ32+AK32+AL32+AM32+AN32+AO32 -> 12 | AQ32: 11/12/2020 | AR32: Results received | AS32: N | AT32: WERO | AU32: N | AV32: 1161005 | AW32: Under Springfield | AX32: health@ludlow.ma.us | AY32: erin.craft@mass.gov | BE32: P-186563
A33: 44397 | B33: 9-Completed | C33: Follow-up | D33: Routine flushing | E33: 44292 | F33: 2021-04-01T14:49:09-05:00 | G33: ccf - 1617306410757 | H33: Brenda's childcare | I33: FCC | J33: 106 Standish Road | L33: Lynn | M33: 01904 | N33: Brenda | O33: Resse | P33: Owner | Q33: 781-599-0567 | R33: Brenskidz@aol.com | S33: 106 Standish Road | U33: Lynn | V33: 1904 | W33: < 1988 | X33: 0-10 | Y33: Resse, Brenda | Z33: cc8e-ac1a-5c57 | AA33: 621335 | AB33: Kate | AC33: Brenda Resse | AD33: 44340 | AE33: 6 | AF33: 6 | AG33: =AE33+AF33 -> 12 | AH33: ConTest | AI33: 44357 | AJ33: 3 | AK33: 6 | AL33: 3 | AM33: 0 | AN33: 0 | AO33: 0 | AP33: =AJ33+AK33+AL33+AM33+AN33+AO33 -> 12 | AQ33: 44363 | AS33: N/Y | AT33: NERO | AU33: N | AV33: 3163000 | AW33: rdawe@lynnwatersewer.org | AX33: mdesmarais@lynnma.gov | AY33: erin.craft@mass.gov | BD33: =IF(ISBLANK(AD33),"",IF(AD33<TODAY(),L33,"")) -> Lynn | BE33: P-182771
A34: 44460 | B34: 9-Completed | C34: No response | E34: 44295 | F34: 2021-04-03T15:53:53-05:00 | G34: ccf - 1617484134292 | H34: Kenia Correa | I34: FCC | J34: 38 Union Street | L34: Methuen | M34: 01844 | N34: kenia | O34: correa | P34: Educator | Q34: 978-885-2456 | R34: keniaco28@gmail.com | S34: 38 Union Street | U34: Methuen | V34: 1844 | W34: < 1988 | X34: 0-10 | Z34: 0477-8ee1-4970 | AA34: 8030957 | AB34: Kate | AC34: kenia Correa | AD34: 44318 | AE34: 2 | AF34: 2 | AG34: =AE34+AF34 -> 4 | AH34: RI Analytical | AI34: 44349 | AJ34: 1 | AK34: 0 | AL34: 1 | AM34: 2 | AN34: 0 | AO34: 0 | AP34: =AJ34+AK34+AL34+AM34+AN34+AO34 -> 4 | AQ34: 44351 | AS34: N | AT34: NERO | AU34: N | AV34: 3181000 | AW34: None | AX34: fzemel@ci.methuen.ma.us | AY34: erin.craft@mass.gov | BD34: =IF(ISBLANK(AD34),"",IF(AD34<TODAY(),L34,"")) -> Methuen | BE34: P-171076
A35: 44377 | B35: 9-Completed | C35: No Detect, Done | E35: 43896 | F35: 2020-01-15T12:00:25-05:00 | G35: ccf - 211923_P-170248 | H35: Small Friends | I35: LG | J35: 21 Nobadeer Farm Road | L35: Nantucket | M35: 02554 | N35: Nichole | O35: Olson | P35: Director | Q35: 508-228-6769 | R35: nolson@smallfriendsnantucket.org | S35: Po Box 2826 | U35: Nantucket | V35: 02584 | W35: > 1988 | X35: 20+ | Z35: 95c9-1e01-89cf | AA35: 211923 | AB35: Rick | AD35: 44047 | AE35: =AJ35+AL35+AN35 -> 9 | AF35: =AK35+AM35+AO35 -> 9 | AG35: =AE35+AF35 -> 18 | AH35: Barnstable | AI35: 44062 | AJ35: 9 | AK35: 9 | AL35: 0 | AM35: 0 | AN35: 0 | AO35: 0 | AP35: =AJ35+AK35+AL35+AM35+AN35+AO35 -> 18 | AQ35: 11/3/2020 | AR35: Notified by phone of ND; waiting on Boston letter for forwarding | AS35: N | AT35: SERO | AU35: N | AV35: 4197000 | AW35: mwillett@nantucket-ma.gov | AX35: roberto.santamaria@ci.everett.ma.us | AY35: erin.craft@mass.gov | BD35: =IF(ISBLANK(AD35),"",IF(AD35<TODAY(),L35,"")) -> Nantucket | BE35: P-187015
A36: 44146 | B36: 9-Completed | C36: No Detect, Done | E36: 44008 | F36: 2020-06-09T11:29:40-05:00 | G36: ccf - 1591720143555 | H36: Cozy Coop | I36: FCC | J36: 122 Durfee Street | L36: New Bedford | M36: 02740 | N36: Viry | O36: Hernandez | P36: Family child care provider | Q36: 781-330-5641 | R36: vmendez18@gmail.com | S36: 122 Durfee St. | U36: New Bedford | V36: 02740 | W36: undefined | X36: undefined | Y36: Hernandez, Viry | Z36: f843-8a60-73c0 | AA36: T0000046 | AB36: Rick | AD36: 44054 | AE36: =AJ36+AL36+AN36 -> 3 | AF36: =AK36+AM36+AO36 -> 2 | AG36: =AE36+AF36 -> 5 | AH36: RI Analytical | AI36: 44063 | AJ36: 3 | AK36: 2 | AL36: 0 | AM36: 0 | AN36: 0 | AO36: 0 | AP36: =AJ36+AK36+AL36+AM36+AN36+AO36 -> 5 | AQ36: 44146 | AR36: Notified by phone of ND; waiting on Boston letter for forwarding | AS36: N | AT36: SERO | AU36: N | AV36: 4201000 | AW36: ymane.galotti@newbedford-ma.gov | AX36: damon.chaplin@newbedford-ma.gov | AY36: erin.craft@mass.gov | BD36: =IF(ISBLANK(AD36),"",IF(AD36<TODAY(),L36,"")) -> New Bedford | BE36: P-170129
A37: 44376 | B37: 9-Completed | C37: No Detect, Done | E37: 44292 | F37: 2021-04-01T14:11:03-05:00 | G37: ccf - 290938_P-170994 | H37: Kindercare Learning Center | I37: LG | J37: 1 Daniel Lucy Way | L37: Newburyport | M37: 01950 | N37: Joanie | O37: Dole | P37: Center Director | Q37: 978-462-5649 | R37: jodole@kindercare.com | S37: 1 Daniel Lucy Way | U37: Newburyport | V37: 1950 | W37: > 1988 | X37: 20+ | AA37: 290938 | AB37: Gene | AC37: Gene Brunelle | AD37: 43973 | AE37: 21 | AF37: 21 | AG37: =AE37+AF37 -> 42 | AH37: RI Analytical | AI37: 44358 | AJ37: 21 | AK37: 21 | AL37: 0 | AM37: 0 | AN37: 0 | AO37: 0 | AP37: =AJ37+AK37+AL37+AM37+AN37+AO37 -> 42 | AQ37: 44376 | AR37: Sites received 5/11 | AS37: N | AT37: NERO | AU37: N | AV37: 3206000 | AW37: None | AX37: fgiacalone@cityofnewburyport.com | AY37: erin.craft@mass.gov
A38: 44224 | B38: 9-Completed | C38: No Detect, Done | E38: 44140 | F38: 2020-09-15T10:33:13-05:00 | G38: sch - 05320010 | H38: HEC Academy | I38: sch | J38: c/o HEC Academy | K38: 97 Hawley Street | L38: Northampton | M38: 01060 | N38: Sherry | O38: Smith | P38: Director of Special Education | Q38: 413-588-5260 | R38: ssmith@collaborative.org | S38: c/o HEC Academy | T38: 97 Hawley Street | U38: Northampton | V38: 01060 | W38: < 1988 | X38: 20+ | Z38: 1db0-55d7-27e1 | AA38: 05320010 | AB38: Kate | AC38: Sherry Smith | AD38: 44202 | AE38: 6 | AF38: 6 | AG38: =AE38+AF38 -> 12 | AH38: Con-Test | AI38: 44214 | AJ38: 2 | AK38: 6 | AL38: 4 | AM38: 0 | AN38: 0 | AO38: 0 | AP38: =AJ38+AK38+AL38+AM38+AN38+AO38 -> 12 | AQ38: 44224 | AR38: Samples Collected 1/6/21 at 7:30AM; Sampling completed 3/10/21 | AS38: N | AT38: WERO | AU38: N | AV38: 1214000 | AW38: dpwinfo@northamptonma.gov | AX38: healthdept@northamptonma.gov | AY38: ruth.e.hersh@mass.gov | BD38: =IF(ISBLANK(AD38),"",IF(AD38<TODAY(),L38,"")) -> Northampton | BE38: P-169407
A39: 44377 | B39: 9-Completed | C39: No Detect, Done | E39: 43895 | F39: 2020-02-04T07:40:00-05:00 | G39: sch - 1580819745259 | H39: 18 Degrees, Early Education and Care Redfield House | I39: LG | J39: 48 Elizabeth Street | L39: Pittsfield | M39: 01201 | N39: Anthony | O39: Anderton | P39: Director of Building and Grounds | Q39: 413-448-8281 x229 | R39: tanderton@18degreesma.org | S39: 480 West St. | U39: Pittsfield | V39: 01201 | W39: < 1988 | X39: 0-10 | Y39: Berkshire Family & Children | Z39: b54e-8200-c8c4 | AA39: 212367 | AB39: Kate | AC39: Tony Anderton | AD39: 44167 | AE39: =AJ39+AL39+AN39 -> 5 | AF39: =AK39+AM39+AO39 -> 5 | AG39: =AE39+AF39 -> 10 | AH39: Con-Test | AI39: 44180 | AJ39: 4 | AK39: 5 | AL39: 1 | AM39: 0 | AN39: 0 | AO39: 0 | AP39: =AJ39+AK39+AL39+AM39+AN39+AO39 -> 10 | AQ39: 12/29/2020 | AR39: Collections completed 12/2. | AS39: N | AT39: WERO | AU39: N | AV39: 1236000 | AW39: bstack@cityofpittsfield.org | AX39: garmstrong@pittsfieldch.com | AY39: erin.craft@mass.gov | BD39: =IF(ISBLANK(AD39),"",IF(AD39<TODAY(),L39,"")) -> Pittsfield | BE39: P-182770
A40: 44377 | B40: 9-Completed | C40: No Detect, Done | E40: 43895 | F40: 2020-01-29T09:46:40-05:00 | G40: ccf - 1580309107002 | H40: 18 Degrees Early Education and Care | I40: LG | J40: 480 West Street | L40: Pittsfield | M40: 01201 | N40: Anthony | O40: Anderton | P40: Director of Building and Grounds | Q40: 413-448-8281 | R40: tanderton@18degreesma.org | S40: 480 West St. | U40: Pittsfield | V40: 01201 | W40: > 1988 | X40: 11-20 | Y40: Berkshire Family & Children | Z40: b54e-8200-c8c4 | AA40: 201332 | AB40: Kate | AC40: Tony Anderton | AD40: 44167 | AE40: =AJ40+AL40+AN40 -> 6 | AF40: =AK40+AM40+AO40 -> 6 | AG40: =AE40+AF40 -> 12 | AH40: Con-Test | AI40: 44180 | AJ40: 6 | AK40: 6 | AL40: 0 | AM40: 0 | AN40: 0 | AO40: 0 | AP40: =AJ40+AK40+AL40+AM40+AN40+AO40 -> 12 | AQ40: 12/29/2020 | AR40: Collections scheduled 12/2. | AS40: N | AT40: WERO | AU40: N | AV40: 1236000 | AW40: bstack@cityofpittsfield.org | AX40: garmstrong@pittsfieldch.com | AY40: erin.craft@mass.gov
...

Sheet Sheet1
A1: Application Date & Time | B1: DATETIME | C1: Facility ID | D1: FACILITY_ID | E1: Facility Name | F1: FACILITY_NAME
A2: 2020-01-14T07:23:11-05:00 | B2: 2020-01-14T07:23:11-05:00 | C2: sch - 04320530 | D2: sch - 1579004422780 | E2: Cape Cod Lighthouse Charter School | F2: Cape Cod Lighthouse Charter School
A3: 2020-01-14T09:04:09-05:00 | B3: 2020-01-14T09:04:09-05:00 | C3: ccf - 8030609_P-184777 | D3: ccf - 8030609_P-184777 | E3: Loving Nest Preschool | F3: Loving Nest Preschool
A4: 2020-01-14T09:12:16-05:00 | B4: 2020-01-14T09:12:16-05:00 | C4: ccf - 2911795_P-177108 | D4: ccf - 2911795_P-177108 | E4: Crayon College, Inc. | F4: Crayon College, Inc.
A5: 2020-01-15T11:23:35-05:00 | B5: 2020-01-15T11:23:35-05:00 | C5: ccf - 8030658_P-184787 | D5: ccf - 8030658_P-184787 | E5: Concord Montessori School | F5: Concord Montessori School
A6: 2020-01-15T12:00:25-05:00 | B6: 2020-01-15T12:00:25-05:00 | C6: ccf - 211923_P-170248 | D6: ccf - 211923_P-170248 | E6: Small Friends | F6: Small Friends
A7: 2020-01-15T12:34:31-05:00 | B7: 2020-01-15T12:34:31-05:00 | C7: ccf - 291012_P-170912 | D7: ccf - 291012_P-170912 | E7: Giggle Garden's, Inc. | F7: Giggle Garden's, Inc.
B8: 2020-01-15T13:13:31-05:00 | D8: ccf - 200592_P-169530 | F8: Sunshine Preschool
A9: 2020-01-16T11:34:23-05:00 | B9: 2020-01-16T11:34:23-05:00 | C9: ccf - 2912100_P-177316 | D9: ccf - 2912100_P-177316 | E9: Our Lady's Child Care Center | F9: Our Lady's Child Care Center
A10: 2020-01-17T17:03:06-05:00 | B10: 2020-01-17T17:03:06-05:00 | C10: ccf - 1579298404811 | D10: ccf - 1579298404811 | E10: Paula's Family ChildCare | F10: Paula's Family ChildCare
A11: 2020-01-18T09:31:43-05:00 | B11: 2020-01-18T09:31:43-05:00 | C11: ccf - 201425_P-169923 | D11: ccf - 201425_P-169923 | E11: Open Center for Children | F11: Open Center for Children
A12: 2020-01-18T11:31:11-05:00 | B12: 2020-01-18T11:31:11-05:00 | C12: ccf - 200415_P-169439 | D12: ccf - 200415_P-169439 | E12: Plymouth House Nursery School | F12: Plymouth House Nursery School
A13: 2020-01-20T15:01:25-05:00 | B13: 2020-01-20T15:01:25-05:00 | C13: ccf - 8032311_P-186321 | D13: ccf - 8032311_P-186321 | E13: Next Generation Childrens Center of Westford, LLC | F13: Next Generation Childrens Center of Westford, LLC
A14: 2020-01-21T14:18:39-05:00 | B14: 2020-01-21T14:18:39-05:00 | C14: ccf - 200410_P-169437 | D14: ccf - 1579633805415 | E14: Framingham Centre Nursery School | F14: Framingham Centre Nursery School
A15: 2020-01-21T15:01:37-05:00 | B15: 2020-01-21T15:01:37-05:00 | C15: ccf - T0000040 | D15: ccf,ccf - 1579636659305 | E15: Pre-K-Kidz Childcare and Preschool | F15: Pre-K-Kidz Childcare and Preschool
B16: 2020-01-21T15:01:37-05:00 | D16: ccf,ccf - 1579636659305 | F16: Pre-K-Kidz Childcare and Preschool
A17: 2020-01-22T13:54:45-05:00 | B17: 2020-01-22T13:54:45-05:00 | C17: sch - 04940205 | D17: sch - 35060505 | E17: Pioneer Charter School of Science | F17: Pioneer Charter School of Science II (PCSS-II)
A18: 2020-01-22T13:54:45-05:00 | B18: 2020-01-22T13:54:45-05:00 | C18: sch - T0000042 | D18: sch - 04940205 | E18: Pioneer Charter School of Science - Network Office | F18: Pioneer Charter School of Science
A19: 2020-01-22T13:54:45-05:00 | B19: 2020-01-22T13:54:45-05:00 | C19: sch - 35060505 | D19: ccf - 1579718750808 | E19: Pioneer Charter School of Science II (PCSS-II) | F19: Pioneer Charter School of Science - Lower School
A20: 2020-01-22T13:54:45-05:00 | B20: 2020-01-22T13:54:45-05:00 | C20: ccf - T0000041 | D20: sch - 1579718782461 | E20: Pioneer Charter School of Science - Lower School | F20: Pioneer Charter School of Science - Network Office
A21: 2020-01-23T08:11:04-05:00 | B21: 2020-01-23T08:11:04-05:00 | C21: ccf - 2911908_P-177208 | D21: ccf - 2911908_P-177208 | E21: Valley Opportunity Council @Churchill Homes | F21: Valley Opportunity Council @Churchill Homes
A22: 2020-01-23T11:37:54-05:00 | B22: 2020-01-23T11:37:54-05:00 | C22: ccf - 200316_P-169404 | D22: ccf - 200316_P-169404 | E22: Cole-Harrington Children's Center | F22: Cole-Harrington Children's Center
A23: 2020-01-23T17:46:27-05:00 | B23: 2020-01-23T17:46:27-05:00 | C23: ccf - 8029897_P-184061 | D23: ccf - 8029897_P-184061 | E23: Tree House Academy Child Care, Inc | F23: Tree House Academy Child Care, Inc
A24: 2020-01-23T17:49:18-05:00 | B24: 2020-01-23T17:49:18-05:00 | C24: ccf - 2912297_P-177490 | D24: ccf - 2912297_P-177490 | E24: Tree House Academy Child Care Inc. | F24: Tree House Academy Child Care Inc.
A25: 2020-01-24T10:49:28-05:00 | B25: 2020-01-24T10:49:28-05:00 | C25: ccf - 8031572 | D25: ccf - 1579880885539 | E25: Marigold Montessori School | F25: Marigold Montessori School
A26: 2020-01-24T12:16:31-05:00 | B26: 2020-01-24T12:16:31-05:00 | C26: ccf - 8032025_P-186284 | D26: ccf - 8032025_P-186284 | E26: Valley Opportunity Council at Sullivan | F26: Valley Opportunity Council at Sullivan
A27: 2020-01-27T12:45:38-05:00 | B27: 2020-01-27T12:45:38-05:00 | C27: ccf - 290320_P-170629 | D27: ccf - 290320_P-170629 | E27: Sunshine Country Day School, Inc. | F27: Sunshine Country Day School, Inc.
A28: 2020-01-27T12:47:42-05:00 | B28: 2020-01-27T12:47:42-05:00 | C28: ccf - 8031914_P-185853 | D28: ccf - 8031914_P-185853 | E28: Sunshine South | F28: Sunshine South
... A34: 2020-01-29T17:51:00-05:00 | B34: 2020-01-29T17:51:00-05:00 | C34: ccf - 212450_P-170547 | D34: ccf - 212450_P-170547 | E34: The Social Sprouts Extended Day Program/Central Square Center | F34: The Social Sprouts Extended Day Program/Central Square Center
B35: 2020-01-30T07:50:41-05:00 | D35: ccf - 2911908_P-177208 | F35: Valley Opportunity Council @Churchill Homes
A36: 2020-01-30T07:53:47-05:00 | B36: 2020-01-30T07:53:47-05:00 | C36: ccf - 290324_P-170630 | D36: ccf - 290324_P-170630 | E36: V. O. C. Child Care on Montgomery Street | F36: V. O. C. Child Care on Montgomery Street
A37: 2020-01-30T08:11:38-05:00 | B37: 2020-01-30T08:11:38-05:00 | C37: ccf - 212650_P-170464 | D37: ccf - 212650_P-170464 | E37: P.A.C.E. Head Start | F37: P.A.C.E. Head Start
A38: 2020-01-30T09:51:12-05:00 | B38: 2020-01-30T09:51:12-05:00 | C38: ccf - 2911803_P-177112 | D38: ccf - 1580395555466 | E38: Valley Opportunity Council At Beaudoin Village | F38: Valley Opportunity Council At Beaudoin Village
A39: 2020-01-30T10:42:36-05:00 | B39: 2020-01-30T10:42:36-05:00 | C39: ccf - 201230_P-169784 | D39: ccf - 201230_P-169784 | E39: Rainbow Child Development Pre School Ctr & School Age | F39: Rainbow Child Development Pre School Ctr & School Age
A40: 2020-01-30T11:33:40-05:00 | B40: 2020-01-30T11:33:40-05:00 | C40: ccf - 201563_P-169959 | D40: ccf - 201563_P-169959 | E40: Chicopee Child Development Center, Inc. | F40: Chicopee Child Development Center, Inc.
A41: 2020-01-30T13:50:09-05:00 | B41: 2020-01-30T13:50:09-05:00 | C41: ccf - 8029093_P-183300 | D41: ccf - 8029093_P-183300 | E41: Harbor City School | F41: Harbor City School
A42: 2020-01-31T09:21:48-05:00 | B42: 2020-01-31T09:21:48-05:00 | C42: ccf,ccf - 211581_P-170300 | D42: ccf,ccf - 211581_P-170300 | E42: Twelfth Baptist Church Christian Preschool | F42: Twelfth Baptist Church Christian Preschool
B43: 2020-01-31T09:21:48-05:00 | D43: ccf,ccf - 211581_P-170300 | F43: Twelfth Baptist Church Christian Preschool
A44: 2020-01-31T10:35:04-05:00 | B44: 2020-01-31T10:35:04-05:00 | C44: ccf - 211381_P-170164 | D44: ccf - 211381_P-170164 | E44: J.F.K. Head Start and Day Care Program | F44: J.F.K. Head Start and Day Care Program
A45: 2020-01-31T14:23:57-05:00 | B45: 2020-01-31T14:23:57-05:00 | C45: ccf - 390378_P-171469 | D45: ccf - 390378_P-171469 | E45: Access Enrichment Program | F45: Access Enrichment Program
...

Sheet stats
A1: EAP Statistics | B1: Total to 2/28/21 | C1: Feb-21 | D1: Total to 3/31/21 | G1: 44256 | H1: Total to 4/30/21 | K1: April 2021
A2: Number of facilities accepted in the program | B2: 111 | C2: 2 | D2: 114 | G2: 3 | H2: =COUNTIF(Facilities!#REF!,"A") -> #REF! | K2: 59*
A3: Number of schools accepted in the program | B3: 11 | C3: 0 | D3: =COUNTIFS(Facilities!#REF!,"A",Facilities!I:I,"sch") -> #REF! | G3: 0 | H3: =COUNTIFS(Facilities!#REF!,"A",Facilities!I:I,"sch") -> #REF! | K3: 0
A4: Number of ECCFs accepted in the program | B4: 100 | C4: 2 | D4: =D2-D3 -> #REF! | G4: 3 | H4: =D2-D3 -> #REF! | K4: 59*
A5: Number of facilities sampled and results received | B5: 39 | C5: 5 | D5: 41 | G5: 2 | H5: =COUNTIFS(Facilities!AI:AI,"<>",Facilities!AI:AI,"<>Out of Program")-1 -> 101 | K5: 2
A6: Number of towns with facilities tested | B6: 28 | D6: 30 | H6: {=SUMPRODUCT(((Facilities!BD2:BD169<>"")/COUNTIF(Facilities!BD2:BD169, Facilities!BD2:BD169 &"")))} -> 70
A7: Number of samples analyzed to-date | B7: 639 | D7: 651 | E7: =SUMIF(Facilities!AI:AI,"<="&TODAY(),Facilities!AP:AP) -> 1493 | F7: =SUMIF(Facilities!AI:AI,TODAY(),Facilities!AP:AP) -> 0 | G7: =D7-B7 -> 12 | H7: 897 | I7: =SUMIF(Facilities!AI:AI,"<="&TODAY(),Facilities!AP:AP) -> 1493 | J7: =SUMIF(Facilities!AI:AI,TODAY(),Facilities!AP:AP) -> 0 | K7: 92
A8: Number of schools results ≤1.4 ppb First Draw | B8: 0 | C8: 9 | D8: 17 | G8: 0 | H8: 35 | K8: 18
A9: Number of school results ≤1.4 ppb Flushed Sample | B9: 0 | C9: 9 | D9: 22 | G9: 0 | H9: 56 | K9: 34
A10: Number of school results 1.5-15.4 ppb First Draw | B10: 0 | C10: 0 | D10: 9 | G10: 0 | H10: 56 | K10: 47
A11: Number of school results 1.5-15.4 ppb Flushed Sample | B11: 0 | C11: 0 | D11: 6 | G11: 0 | H11: 34 | K11: 28
A12: Number of school results ≥ 15.5 First Draw | B12: 0 | C12: 0 | D12: 4 | G12: 0 | H12: 12 | K12: 8
A13: Number of school results ≥ 15.5 pbb Flushed Sample | B13: 0 | C13: 0 | D13: 2 | G13: 0 | H13: 5 | K13: 3
A14: Number of EECFs results ≤1.4 ppb First Draw | B14: 231 | C14: 8 | D14: 235 | G14: 4 | H14: 257 | K14: 31
A15: Number of EECFs results ≤1.4 ppb Flushed Sample | B15: 269 | C15: 11 | D15: 275 | G15: 6 | H15: 305 | K15: 44
A16: Number of EECFs results 1.5-15.4 ppb First Draw | B16: 95 | C16: 4 | D16: 97 | G16: 2 | H16: 101 | K16: 13
A17: Number of EECFs results 1.5-15.4 ppb Flushed Sample | B17: 28 | C17: 2 | D17: 28 | G17: 0 | H17: 24 | K17: 2
A18: Number of EECFs results ≥ 15.5 pbb First Draw | B18: 12 | C18: 1 | D18: 12 | G18: 0 | H18: 10 | K18: 2
A19: Number of EECFs results ≥ 15.5 pbb Flushed Sample | B19: 4 | C19: 0 | D19: 4 | G19: 0 | H19: 2 | K19: 0
K20: * One closed and won't participate
A22: EAP Statistics | B22: Total to 4/30/21 | C22: April 2021
A23: Number of facilities accepted in the program | B23: 172 | C23: 59*
A24: Number of schools accepted in the program | B24: 11 | C24: 0
A25: Number of ECCFs accepted in the program | B25: 103 | C25: 59*
A26: Number of facilities sampled and results received | B26: 43 | C26: 2
A27: Number of towns with facilities tested | B27: 36
A28: Number of samples analyzed to-date | B28: 897 | C28: 92
A29: Number of schools results ≤1.4 ppb First Draw | B29: 35 | C29: 18
A30: Number of school results ≤1.4 ppb Flushed Sample | B30: 56 | C30: 34
A31: Number of school results 1.5-15.4 ppb First Draw | B31: 56 | C31: 47
A32: Number of school results 1.5-15.4 ppb Flushed Sample | B32: 34 | C32: 28
A33: Number of school results ≥ 15.5 First Draw | B33: 12 | C33: 8
A34: Number of school results ≥ 15.5 pbb Flushed Sample | B34: 5 | C34: 3
A35: Number of EECFs results ≤1.4 ppb First Draw | B35: 257 | C35: 31
A36: Number of EECFs results ≤1.4 ppb Flushed Sample | B36: 305 | C36: 44
A37: Number of EECFs results 1.5-15.4 ppb First Draw | B37: 101 | C37: 13
A38: Number of EECFs results 1.5-15.4 ppb Flushed Sample | B38: 24 | C38: 2
A39: Number of EECFs results ≥ 15.5 pbb First Draw | B39: 10 | C39: 2
A40: Number of EECFs results ≥ 15.5 pbb Flushed Sample | B40: 2 | C40: 0
